Workbook

Sheet ANJALI
A1: STAFF | B1: Vehicle No | C1: Owner Name | D1: Fitness Validity | E1: GVW (In Kg.) | F1: Registration Date | G1: CONTACT | H1: MESSAGE | I1: RESPONSE
A2: ANJALI-8141489538 | B2: GJ36W2626 | C2: PRAVINABEN DAKSHINI | D2: 46023 | E2: 818 | F2: 45323 | G2: 7621002850 | H2: ="💬 *TORQUE AUTO ADVISOR – FITNESS / PASSING REMINDER* " & CHAR(10) & "📍 *Morbi*" & CHAR(10) & CHAR(10) & "🧾 *શ્રી " & C2 & " sir*, તમારી ગાડી *" & B2 & "* નું *પાસિંગ (Fitness) તા. " & TEXT(D2,"DD-MM-yyyy") & "* એ પૂરું થાય છે." & CHAR(10) & CHAR(10) & "⚠️ પાસિંગ સમયસર ન કરાવવાથી ઓનલાઇન મેમો આવી શકે છે. કૃપા કરીને પાસિંગ નિયમિત રીતે કરાવજો.પાસિંગ ચાલુ ના હોય તો વીમા ક્લેમ પાસ થતો નથી." & CHAR(10) & CHAR(10) & "✅ અમારી પાસે પાસિંગ, પરમીટ, લાઇસન્સ, નામ ટ્રાન્સફર, વીમો વગેરે RTO ને લગતી તમામ સર્વિસ ઉપલબ્ધ છે. —" & CHAR(10) & "📞 સંપર્ક કરો: " & A2 & " | 8141488962" & CHAR(10) & CHAR(10) & "🏢 *ટોર્ક ઓટો એડવાઇઝર*" & CHAR(10) & "બીજા માળે, જીલ કોમ્પલેક્સ, અયોધ્યાપૂરી રોડ," & CHAR(10) & "જૂના બસ સ્ટેન્ડ પાસે, મોરબી" & CHAR(10) & CHAR(10) & "🌐 www.torqueautoadvisor.com" & CHAR(10) & "✉️ info@torqueautoadvisor.com" & CHAR(10) & CHAR(10) & "GST No. 24ALBPL1123D1ZY" & CHAR(10) & "IRDA Code: 1980390000" & CHAR(10) & "MSME: UDYAM-GJ-32-0014559"& CHAR(10) & CHAR(10) & "📍 Office Location: https://share.google/IdNJCnrf2jFCWten6" -> 💬 *TORQUE AUTO ADVISOR – FITNESS / PASSING REMINDER* 📍 *Morbi* 🧾 *શ્રી PRAVINABEN DAKSHINI sir*, તમારી ગાડી *GJ36W2626* નું *પાસિંગ (Fitness) તા. 01-01-2026* એ પૂરું થાય છે. ⚠️ પાસિંગ સમયસર ન કરાવવાથી ઓનલાઇન મેમો આવી શકે છે. કૃપા કરીને પાસિંગ નિયમિત રીતે કરાવજો.પાસિંગ ચાલુ ના હોય તો વીમા ક્લેમ પાસ થતો નથી. ✅ અમારી પાસે પાસિંગ, પરમીટ, લાઇસન્સ, નામ ટ્રાન્સફર, વીમો વગેરે RTO ને લગતી તમામ સર્વિસ ઉપલબ્ધ છે. — 📞 સંપર્ક કરો: ANJALI-8141489538 | 8141488962 🏢 *ટોર્ક ઓટો એડવાઇઝર* બીજા માળે, જીલ કોમ્પલેક્સ, અયોધ્યાપૂરી રોડ, જૂના બસ સ્ટેન્ડ પાસે, મોરબી 🌐 www.torqueautoadvisor.com ✉️ info@torqueautoadvisor.com GST No. 24ALBPL1123D1ZY IRDA Code: 1980390000 MSME: UDYAM-GJ-32-0014559 📍 Office Location: https://share.google/IdNJCnrf2jFCWten6
A3: ANJALI-8141489538 | B3: GJ36V5839 | C3: RAJUBHAI BABUBHAI GOHIL | D3: 46023 | E3: 1600 | F3: 45323 | G3: 9054222788 | H3: ="💬 *TORQUE AUTO ADVISOR – FITNESS / PASSING REMINDER* " & CHAR(10) & "📍 *Morbi*" & CHAR(10) & CHAR(10) & "🧾 *શ્રી " & C3 & " sir*, તમારી ગાડી *" & B3 & "* નું *પાસિંગ (Fitness) તા. " & TEXT(D3,"DD-MM-yyyy") & "* એ પૂરું થાય છે." & CHAR(10) & CHAR(10) & "⚠️ પાસિંગ સમયસર ન કરાવવાથી ઓનલાઇન મેમો આવી શકે છે. કૃપા કરીને પાસિંગ નિયમિત રીતે કરાવજો.પાસિંગ ચાલુ ના હોય તો વીમા ક્લેમ પાસ થતો નથી." & CHAR(10) & CHAR(10) & "✅ અમારી પાસે પાસિંગ, પરમીટ, લાઇસન્સ, નામ ટ્રાન્સફર, વીમો વગેરે RTO ને લગતી તમામ સર્વિસ ઉપલબ્ધ છે. —" & CHAR(10) & "📞 સંપર્ક કરો: " & A3 & " | 8141488962" & CHAR(10) & CHAR(10) & "🏢 *ટોર્ક ઓટો એડવાઇઝર*" & CHAR(10) & "બીજા માળે, જીલ કોમ્પલેક્સ, અયોધ્યાપૂરી રોડ," & CHAR(10) & "જૂના બસ સ્ટેન્ડ પાસે, મોરબી" & CHAR(10) & CHAR(10) & "🌐 www.torqueautoadvisor.com" & CHAR(10) & "✉️ info@torqueautoadvisor.com" & CHAR(10) & CHAR(10) & "GST No. 24ALBPL1123D1ZY" & CHAR(10) & "IRDA Code: 1980390000" & CHAR(10) & "MSME: UDYAM-GJ-32-0014559"& CHAR(10) & CHAR(10) & "📍 Office Location: https://share.google/IdNJCnrf2jFCWten6" -> 💬 *TORQUE AUTO ADVISOR – FITNESS / PASSING REMINDER* 📍 *Morbi* 🧾 *શ્રી RAJUBHAI BABUBHAI GOHIL sir*, તમારી ગાડી *GJ36V5839* નું *પાસિંગ (Fitness) તા. 01-01-2026* એ પૂરું થાય છે. ⚠️ પાસિંગ સમયસર ન કરાવવાથી ઓનલાઇન મેમો આવી શકે છે. કૃપા કરીને પાસિંગ નિયમિત રીતે કરાવજો.પાસિંગ ચાલુ ના હોય તો વીમા ક્લેમ પાસ થતો નથી. ✅ અમારી પાસે પાસિંગ, પરમીટ, લાઇસન્સ, નામ ટ્રાન્સફર, વીમો વગેરે RTO ને લગતી તમામ સર્વિસ ઉપલબ્ધ છે. — 📞 સંપર્ક કરો: ANJALI-8141489538 | 8141488962 🏢 *ટોર્ક ઓટો એડવાઇઝર* બીજા માળે, જીલ કોમ્પલેક્સ, અયોધ્યાપૂરી રોડ, જૂના બસ સ્ટેન્ડ પાસે, મોરબી 🌐 www.torqueautoadvisor.com ✉️ info@torqueautoadvisor.com GST No. 24ALBPL1123D1ZY IRDA Code: 1980390000 MSME: UDYAM-GJ-32-0014559 📍 Office Location: https://share.google/IdNJCnrf2jFCWten6
A4: ANJALI-8141489538 | B4: GJ03BZ7548 | C4: CHANIYA ISMAIL | D4: 46023 | E4: 35000 | F4: 24/12/14 | G4: 9723098830 | H4: ="💬 *TORQUE AUTO ADVISOR – FITNESS / PASSING REMINDER* " & CHAR(10) & "📍 *Morbi*" & CHAR(10) & CHAR(10) & "🧾 *શ્રી " & C4 & " sir*, તમારી ગાડી *" & B4 & "* નું *પાસિંગ (Fitness) તા. " & TEXT(D4,"DD-MM-yyyy") & "* એ પૂરું થાય છે." & CHAR(10) & CHAR(10) & "⚠️ પાસિંગ સમયસર ન કરાવવાથી ઓનલાઇન મેમો આવી શકે છે. કૃપા કરીને પાસિંગ નિયમિત રીતે કરાવજો.પાસિંગ ચાલુ ના હોય તો વીમા ક્લેમ પાસ થતો નથી." & CHAR(10) & CHAR(10) & "✅ અમારી પાસે પાસિંગ, પરમીટ, લાઇસન્સ, નામ ટ્રાન્સફર, વીમો વગેરે RTO ને લગતી તમામ સર્વિસ ઉપલબ્ધ છે. —" & CHAR(10) & "📞 સંપર્ક કરો: " & A4 & " | 8141488962" & CHAR(10) & CHAR(10) & "🏢 *ટોર્ક ઓટો એડવાઇઝર*" & CHAR(10) & "બીજા માળે, જીલ કોમ્પલેક્સ, અયોધ્યાપૂરી રોડ," & CHAR(10) & "જૂના બસ સ્ટેન્ડ પાસે, મોરબી" & CHAR(10) & CHAR(10) & "🌐 www.torqueautoadvisor.com" & CHAR(10) & "✉️ info@torqueautoadvisor.com" & CHAR(10) & CHAR(10) & "GST No. 24ALBPL1123D1ZY" & CHAR(10) & "IRDA Code: 1980390000" & CHAR(10) & "MSME: UDYAM-GJ-32-0014559"& CHAR(10) & CHAR(10) & "📍 Office Location: https://share.google/IdNJCnrf2jFCWten6" -> 💬 *TORQUE AUTO ADVISOR – FITNESS / PASSING REMINDER* 📍 *Morbi* 🧾 *શ્રી CHANIYA ISMAIL sir*, તમારી ગાડી *GJ03BZ7548* નું *પાસિંગ (Fitness) તા. 01-01-2026* એ પૂરું થાય છે. ⚠️ પાસિંગ સમયસર ન કરાવવાથી ઓનલાઇન મેમો આવી શકે છે. કૃપા કરીને પાસિંગ નિયમિત રીતે કરાવજો.પાસિંગ ચાલુ ના હોય તો વીમા ક્લેમ પાસ થતો નથી. ✅ અમારી પાસે પાસિંગ, પરમીટ, લાઇસન્સ, નામ ટ્રાન્સફર, વીમો વગેરે RTO ને લગતી તમામ સર્વિસ ઉપલબ્ધ છે. — 📞 સંપર્ક કરો: ANJALI-8141489538 | 8141488962 🏢 *ટોર્ક ઓટો એડવાઇઝર* બીજા માળે, જીલ કોમ્પલેક્સ, અયોધ્યાપૂરી રોડ, જૂના બસ સ્ટેન્ડ પાસે, મોરબી 🌐 www.torqueautoadvisor.com ✉️ info@torqueautoadvisor.com GST No. 24ALBPL1123D1ZY IRDA Code: 1980390000 MSME: UDYAM-GJ-32-0014559 📍 Office Location: https://share.google/IdNJCnrf2jFCWten6
A5: ANJALI-8141489538 | B5: GJ36T6417 | C5: JIVANBHAI | D5: 46023 | E5: 2670 | F5: 43132 | G5: 9726598420 | H5: ="💬 *TORQUE AUTO ADVISOR – FITNESS / PASSING REMINDER* " & CHAR(10) & "📍 *Morbi*" & CHAR(10) & CHAR(10) & "🧾 *શ્રી " & C5 & " sir*, તમારી ગાડી *" & B5 & "* નું *પાસિંગ (Fitness) તા. " & TEXT(D5,"DD-MM-yyyy") & "* એ પૂરું થાય છે." & CHAR(10) & CHAR(10) & "⚠️ પાસિંગ સમયસર ન કરાવવાથી ઓનલાઇન મેમો આવી શકે છે. કૃપા કરીને પાસિંગ નિયમિત રીતે કરાવજો.પાસિંગ ચાલુ ના હોય તો વીમા ક્લેમ પાસ થતો નથી." & CHAR(10) & CHAR(10) & "✅ અમારી પાસે પાસિંગ, પરમીટ, લાઇસન્સ, નામ ટ્રાન્સફર, વીમો વગેરે RTO ને લગતી તમામ સર્વિસ ઉપલબ્ધ છે. —" & CHAR(10) & "📞 સંપર્ક કરો: " & A5 & " | 8141488962" & CHAR(10) & CHAR(10) & "🏢 *ટોર્ક ઓટો એડવાઇઝર*" & CHAR(10) & "બીજા માળે, જીલ કોમ્પલેક્સ, અયોધ્યાપૂરી રોડ," & CHAR(10) & "જૂના બસ સ્ટેન્ડ પાસે, મોરબી" & CHAR(10) & CHAR(10) & "🌐 www.torqueautoadvisor.com" & CHAR(10) & "✉️ info@torqueautoadvisor.com" & CHAR(10) & CHAR(10) & "GST No. 24ALBPL1123D1ZY" & CHAR(10) & "IRDA Code: 1980390000" & CHAR(10) & "MSME: UDYAM-GJ-32-0014559"& CHAR(10) & CHAR(10) & "📍 Office Location: https://share.google/IdNJCnrf2jFCWten6" -> 💬 *TORQUE AUTO ADVISOR – FITNESS / PASSING REMINDER* 📍 *Morbi* 🧾 *શ્રી JIVANBHAI sir*, તમારી ગાડી *GJ36T6417* નું *પાસિંગ (Fitness) તા. 01-01-2026* એ પૂરું થાય છે. ⚠️ પાસિંગ સમયસર ન કરાવવાથી ઓનલાઇન મેમો આવી શકે છે. કૃપા કરીને પાસિંગ નિયમિત રીતે કરાવજો.પાસિંગ ચાલુ ના હોય તો વીમા ક્લેમ પાસ થતો નથી. ✅ અમારી પાસે પાસિંગ, પરમીટ, લાઇસન્સ, નામ ટ્રાન્સફર, વીમો વગેરે RTO ને લગતી તમામ સર્વિસ ઉપલબ્ધ છે. — 📞 સંપર્ક કરો: ANJALI-8141489538 | 8141488962 🏢 *ટોર્ક ઓટો એડવાઇઝર* બીજા માળે, જીલ કોમ્પલેક્સ, અયોધ્યાપૂરી રોડ, જૂના બસ સ્ટેન્ડ પાસે, મોરબી 🌐 www.torqueautoadvisor.com ✉️ info@torqueautoadvisor.com GST No. 24ALBPL1123D1ZY IRDA Code: 1980390000 MSME: UDYAM-GJ-32-0014559 📍 Office Location: https://share.google/IdNJCnrf2jFCWten6
A6: ANJALI-8141489538 | B6: GJ13W1023 | C6: RAHEMTULLABHAI | D6: 46023 | E6: 2880 | F6: 20/01/11 | G6: 9825497363 | H6: ="💬 *TORQUE AUTO ADVISOR – FITNESS / PASSING REMINDER* " & CHAR(10) & "📍 *Morbi*" & CHAR(10) & CHAR(10) & "🧾 *શ્રી " & C6 & " sir*, તમારી ગાડી *" & B6 & "* નું *પાસિંગ (Fitness) તા. " & TEXT(D6,"DD-MM-yyyy") & "* એ પૂરું થાય છે." & CHAR(10) & CHAR(10) & "⚠️ પાસિંગ સમયસર ન કરાવવાથી ઓનલાઇન મેમો આવી શકે છે. કૃપા કરીને પાસિંગ નિયમિત રીતે કરાવજો.પાસિંગ ચાલુ ના હોય તો વીમા ક્લેમ પાસ થતો નથી." & CHAR(10) & CHAR(10) & "✅ અમારી પાસે પાસિંગ, પરમીટ, લાઇસન્સ, નામ ટ્રાન્સફર, વીમો વગેરે RTO ને લગતી તમામ સર્વિસ ઉપલબ્ધ છે. —" & CHAR(10) & "📞 સંપર્ક કરો: " & A6 & " | 8141488962" & CHAR(10) & CHAR(10) & "🏢 *ટોર્ક ઓટો એડવાઇઝર*" & CHAR(10) & "બીજા માળે, જીલ કોમ્પલેક્સ, અયોધ્યાપૂરી રોડ," & CHAR(10) & "જૂના બસ સ્ટેન્ડ પાસે, મોરબી" & CHAR(10) & CHAR(10) & "🌐 www.torqueautoadvisor.com" & CHAR(10) & "✉️ info@torqueautoadvisor.com" & CHAR(10) & CHAR(10) & "GST No. 24ALBPL1123D1ZY" & CHAR(10) & "IRDA Code: 1980390000" & CHAR(10) & "MSME: UDYAM-GJ-32-0014559"& CHAR(10) & CHAR(10) & "📍 Office Location: https://share.google/IdNJCnrf2jFCWten6" -> 💬 *TORQUE AUTO ADVISOR – FITNESS / PASSING REMINDER* 📍 *Morbi* 🧾 *શ્રી RAHEMTULLABHAI sir*, તમારી ગાડી *GJ13W1023* નું *પાસિંગ (Fitness) તા. 01-01-2026* એ પૂરું થાય છે. ⚠️ પાસિંગ સમયસર ન કરાવવાથી ઓનલાઇન મેમો આવી શકે છે. કૃપા કરીને પાસિંગ નિયમિત રીતે કરાવજો.પાસિંગ ચાલુ ના હોય તો વીમા ક્લેમ પાસ થતો નથી. ✅ અમારી પાસે પાસિંગ, પરમીટ, લાઇસન્સ, નામ ટ્રાન્સફર, વીમો વગેરે RTO ને લગતી તમામ સર્વિસ ઉપલબ્ધ છે. — 📞 સંપર્ક કરો: ANJALI-8141489538 | 8141488962 🏢 *ટોર્ક ઓટો એડવાઇઝર* બીજા માળે, જીલ કોમ્પલેક્સ, અયોધ્યાપૂરી રોડ, જૂના બસ સ્ટેન્ડ પાસે, મોરબી 🌐 www.torqueautoadvisor.com ✉️ info@torqueautoadvisor.com GST No. 24ALBPL1123D1ZY IRDA Code: 1980390000 MSME: UDYAM-GJ-32-0014559 📍 Office Location: https://share.google/IdNJCnrf2jFCWten6
A7: ANJALI-8141489538 | B7: GJ36V5834 | C7: KANTILAL | D7: 46023 | E7: 1630 | F7: 45323 | G7: 9978198437 | H7: ="💬 *TORQUE AUTO ADVISOR – FITNESS / PASSING REMINDER* " & CHAR(10) & "📍 *Morbi*" & CHAR(10) & CHAR(10) & "🧾 *શ્રી " & C7 & " sir*, તમારી ગાડી *" & B7 & "* નું *પાસિંગ (Fitness) તા. " & TEXT(D7,"DD-MM-yyyy") & "* એ પૂરું થાય છે." & CHAR(10) & CHAR(10) & "⚠️ પાસિંગ સમયસર ન કરાવવાથી ઓનલાઇન મેમો આવી શકે છે. કૃપા કરીને પાસિંગ નિયમિત રીતે કરાવજો.પાસિંગ ચાલુ ના હોય તો વીમા ક્લેમ પાસ થતો નથી." & CHAR(10) & CHAR(10) & "✅ અમારી પાસે પાસિંગ, પરમીટ, લાઇસન્સ, નામ ટ્રાન્સફર, વીમો વગેરે RTO ને લગતી તમામ સર્વિસ ઉપલબ્ધ છે. —" & CHAR(10) & "📞 સંપર્ક કરો: " & A7 & " | 8141488962" & CHAR(10) & CHAR(10) & "🏢 *ટોર્ક ઓટો એડવાઇઝર*" & CHAR(10) & "બીજા માળે, જીલ કોમ્પલેક્સ, અયોધ્યાપૂરી રોડ," & CHAR(10) & "જૂના બસ સ્ટેન્ડ પાસે, મોરબી" & CHAR(10) & CHAR(10) & "🌐 www.torqueautoadvisor.com" & CHAR(10) & "✉️ info@torqueautoadvisor.com" & CHAR(10) & CHAR(10) & "GST No. 24ALBPL1123D1ZY" & CHAR(10) & "IRDA Code: 1980390000" & CHAR(10) & "MSME: UDYAM-GJ-32-0014559"& CHAR(10) & CHAR(10) & "📍 Office Location: https://share.google/IdNJCnrf2jFCWten6" -> 💬 *TORQUE AUTO ADVISOR – FITNESS / PASSING REMINDER* 📍 *Morbi* 🧾 *શ્રી KANTILAL sir*, તમારી ગાડી *GJ36V5834* નું *પાસિંગ (Fitness) તા. 01-01-2026* એ પૂરું થાય છે. ⚠️ પાસિંગ સમયસર ન કરાવવાથી ઓનલાઇન મેમો આવી શકે છે. કૃપા કરીને પાસિંગ નિયમિત રીતે કરાવજો.પાસિંગ ચાલુ ના હોય તો વીમા ક્લેમ પાસ થતો નથી. ✅ અમારી પાસે પાસિંગ, પરમીટ, લાઇસન્સ, નામ ટ્રાન્સફર, વીમો વગેરે RTO ને લગતી તમામ સર્વિસ ઉપલબ્ધ છે. — 📞 સંપર્ક કરો: ANJALI-8141489538 | 8141488962 🏢 *ટોર્ક ઓટો એડવાઇઝર* બીજા માળે, જીલ કોમ્પલેક્સ, અયોધ્યાપૂરી રોડ, જૂના બસ સ્ટેન્ડ પાસે, મોરબી 🌐 www.torqueautoadvisor.com ✉️ info@torqueautoadvisor.com GST No. 24ALBPL1123D1ZY IRDA Code: 1980390000 MSME: UDYAM-GJ-32-0014559 📍 Office Location: https://share.google/IdNJCnrf2jFCWten6
A8: ANJALI-8141489538 | B8: GJ03AW9900 | C8: CHOSALA LAKHABHAI | D8: 46023 | E8: 15560 | F8: 40212 | G8: 9998885248 | H8: ="💬 *TORQUE AUTO ADVISOR – FITNESS / PASSING REMINDER* " & CHAR(10) & "📍 *Morbi*" & CHAR(10) & CHAR(10) & "🧾 *શ્રી " & C8 & " sir*, તમારી ગાડી *" & B8 & "* નું *પાસિંગ (Fitness) તા. " & TEXT(D8,"DD-MM-yyyy") & "* એ પૂરું થાય છે." & CHAR(10) & CHAR(10) & "⚠️ પાસિંગ સમયસર ન કરાવવાથી ઓનલાઇન મેમો આવી શકે છે. કૃપા કરીને પાસિંગ નિયમિત રીતે કરાવજો.પાસિંગ ચાલુ ના હોય તો વીમા ક્લેમ પાસ થતો નથી." & CHAR(10) & CHAR(10) & "✅ અમારી પાસે પાસિંગ, પરમીટ, લાઇસન્સ, નામ ટ્રાન્સફર, વીમો વગેરે RTO ને લગતી તમામ સર્વિસ ઉપલબ્ધ છે. —" & CHAR(10) & "📞 સંપર્ક કરો: " & A8 & " | 8141488962" & CHAR(10) & CHAR(10) & "🏢 *ટોર્ક ઓટો એડવાઇઝર*" & CHAR(10) & "બીજા માળે, જીલ કોમ્પલેક્સ, અયોધ્યાપૂરી રોડ," & CHAR(10) & "જૂના બસ સ્ટેન્ડ પાસે, મોરબી" & CHAR(10) & CHAR(10) & "🌐 www.torqueautoadvisor.com" & CHAR(10) & "✉️ info@torqueautoadvisor.com" & CHAR(10) & CHAR(10) & "GST No. 24ALBPL1123D1ZY" & CHAR(10) & "IRDA Code: 1980390000" & CHAR(10) & "MSME: UDYAM-GJ-32-0014559"& CHAR(10) & CHAR(10) & "📍 Office Location: https://share.google/IdNJCnrf2jFCWten6" -> 💬 *TORQUE AUTO ADVISOR – FITNESS / PASSING REMINDER* 📍 *Morbi* 🧾 *શ્રી CHOSALA LAKHABHAI sir*, તમારી ગાડી *GJ03AW9900* નું *પાસિંગ (Fitness) તા. 01-01-2026* એ પૂરું થાય છે. ⚠️ પાસિંગ સમયસર ન કરાવવાથી ઓનલાઇન મેમો આવી શકે છે. કૃપા કરીને પાસિંગ નિયમિત રીતે કરાવજો.પાસિંગ ચાલુ ના હોય તો વીમા ક્લેમ પાસ થતો નથી. ✅ અમારી પાસે પાસિંગ, પરમીટ, લાઇસન્સ, નામ ટ્રાન્સફર, વીમો વગેરે RTO ને લગતી તમામ સર્વિસ ઉપલબ્ધ છે. — 📞 સંપર્ક કરો: ANJALI-8141489538 | 8141488962 🏢 *ટોર્ક ઓટો એડવાઇઝર* બીજા માળે, જીલ કોમ્પલેક્સ, અયોધ્યાપૂરી રોડ, જૂના બસ સ્ટેન્ડ પાસે, મોરબી 🌐 www.torqueautoadvisor.com ✉️ info@torqueautoadvisor.com GST No. 24ALBPL1123D1ZY IRDA Code: 1980390000 MSME: UDYAM-GJ-32-0014559 📍 Office Location: https://share.google/IdNJCnrf2jFCWten6
A9: ANJALI-8141489538 | B9: GJ16W1717 | C9: RAJESHBHAI | D9: 46024 | E9: 18500 | F9: 41122 | G9: 8155802014 | H9: ="💬 *TORQUE AUTO ADVISOR – FITNESS / PASSING REMINDER* " & CHAR(10) & "📍 *Morbi*" & CHAR(10) & CHAR(10) & "🧾 *શ્રી " & C9 & " sir*, તમારી ગાડી *" & B9 & "* નું *પાસિંગ (Fitness) તા. " & TEXT(D9,"DD-MM-yyyy") & "* એ પૂરું થાય છે." & CHAR(10) & CHAR(10) & "⚠️ પાસિંગ સમયસર ન કરાવવાથી ઓનલાઇન મેમો આવી શકે છે. કૃપા કરીને પાસિંગ નિયમિત રીતે કરાવજો.પાસિંગ ચાલુ ના હોય તો વીમા ક્લેમ પાસ થતો નથી." & CHAR(10) & CHAR(10) & "✅ અમારી પાસે પાસિંગ, પરમીટ, લાઇસન્સ, નામ ટ્રાન્સફર, વીમો વગેરે RTO ને લગતી તમામ સર્વિસ ઉપલબ્ધ છે. —" & CHAR(10) & "📞 સંપર્ક કરો: " & A9 & " | 8141488962" & CHAR(10) & CHAR(10) & "🏢 *ટોર્ક ઓટો એડવાઇઝર*" & CHAR(10) & "બીજા માળે, જીલ કોમ્પલેક્સ, અયોધ્યાપૂરી રોડ," & CHAR(10) & "જૂના બસ સ્ટેન્ડ પાસે, મોરબી" & CHAR(10) & CHAR(10) & "🌐 www.torqueautoadvisor.com" & CHAR(10) & "✉️ info@torqueautoadvisor.com" & CHAR(10) & CHAR(10) & "GST No. 24ALBPL1123D1ZY" & CHAR(10) & "IRDA Code: 1980390000" & CHAR(10) & "MSME: UDYAM-GJ-32-0014559"& CHAR(10) & CHAR(10) & "📍 Office Location: https://share.google/IdNJCnrf2jFCWten6" -> 💬 *TORQUE AUTO ADVISOR – FITNESS / PASSING REMINDER* 📍 *Morbi* 🧾 *શ્રી RAJESHBHAI sir*, તમારી ગાડી *GJ16W1717* નું *પાસિંગ (Fitness) તા. 02-01-2026* એ પૂરું થાય છે. ⚠️ પાસિંગ સમયસર ન કરાવવાથી ઓનલાઇન મેમો આવી શકે છે. કૃપા કરીને પાસિંગ નિયમિત રીતે કરાવજો.પાસિંગ ચાલુ ના હોય તો વીમા ક્લેમ પાસ થતો નથી. ✅ અમારી પાસે પાસિંગ, પરમીટ, લાઇસન્સ, નામ ટ્રાન્સફર, વીમો વગેરે RTO ને લગતી તમામ સર્વિસ ઉપલબ્ધ છે. — 📞 સંપર્ક કરો: ANJALI-8141489538 | 8141488962 🏢 *ટોર્ક ઓટો એડવાઇઝર* બીજા માળે, જીલ કોમ્પલેક્સ, અયોધ્યાપૂરી રોડ, જૂના બસ સ્ટેન્ડ પાસે, મોરબી 🌐 www.torqueautoadvisor.com ✉️ info@torqueautoadvisor.com GST No. 24ALBPL1123D1ZY IRDA Code: 1980390000 MSME: UDYAM-GJ-32-0014559 📍 Office Location: https://share.google/IdNJCnrf2jFCWten6
A10: ANJALI-8141489538 | B10: GJ03AV8220 | C10: JITENDRA | D10: 46024 | E10: 1550 | F10: 40483 | G10: 8999999999 | H10: ="💬 *TORQUE AUTO ADVISOR – FITNESS / PASSING REMINDER* " & CHAR(10) & "📍 *Morbi*" & CHAR(10) & CHAR(10) & "🧾 *શ્રી " & C10 & " sir*, તમારી ગાડી *" & B10 & "* નું *પાસિંગ (Fitness) તા. " & TEXT(D10,"DD-MM-yyyy") & "* એ પૂરું થાય છે." & CHAR(10) & CHAR(10) & "⚠️ પાસિંગ સમયસર ન કરાવવાથી ઓનલાઇન મેમો આવી શકે છે. કૃપા કરીને પાસિંગ નિયમિત રીતે કરાવજો.પાસિંગ ચાલુ ના હોય તો વીમા ક્લેમ પાસ થતો નથી." & CHAR(10) & CHAR(10) & "✅ અમારી પાસે પાસિંગ, પરમીટ, લાઇસન્સ, નામ ટ્રાન્સફર, વીમો વગેરે RTO ને લગતી તમામ સર્વિસ ઉપલબ્ધ છે. —" & CHAR(10) & "📞 સંપર્ક કરો: " & A10 & " | 8141488962" & CHAR(10) & CHAR(10) & "🏢 *ટોર્ક ઓટો એડવાઇઝર*" & CHAR(10) & "બીજા માળે, જીલ કોમ્પલેક્સ, અયોધ્યાપૂરી રોડ," & CHAR(10) & "જૂના બસ સ્ટેન્ડ પાસે, મોરબી" & CHAR(10) & CHAR(10) & "🌐 www.torqueautoadvisor.com" & CHAR(10) & "✉️ info@torqueautoadvisor.com" & CHAR(10) & CHAR(10) & "GST No. 24ALBPL1123D1ZY" & CHAR(10) & "IRDA Code: 1980390000" & CHAR(10) & "MSME: UDYAM-GJ-32-0014559"& CHAR(10) & CHAR(10) & "📍 Office Location: https://share.google/IdNJCnrf2jFCWten6" -> 💬 *TORQUE AUTO ADVISOR – FITNESS / PASSING REMINDER* 📍 *Morbi* 🧾 *શ્રી JITENDRA sir*, તમારી ગાડી *GJ03AV8220* નું *પાસિંગ (Fitness) તા. 02-01-2026* એ પૂરું થાય છે. ⚠️ પાસિંગ સમયસર ન કરાવવાથી ઓનલાઇન મેમો આવી શકે છે. કૃપા કરીને પાસિંગ નિયમિત રીતે કરાવજો.પાસિંગ ચાલુ ના હોય તો વીમા ક્લેમ પાસ થતો નથી. ✅ અમારી પાસે પાસિંગ, પરમીટ, લાઇસન્સ, નામ ટ્રાન્સફર, વીમો વગેરે RTO ને લગતી તમામ સર્વિસ ઉપલબ્ધ છે. — 📞 સંપર્ક કરો: ANJALI-8141489538 | 8141488962 🏢 *ટોર્ક ઓટો એડવાઇઝર* બીજા માળે, જીલ કોમ્પલેક્સ, અયોધ્યાપૂરી રોડ, જૂના બસ સ્ટેન્ડ પાસે, મોરબી 🌐 www.torqueautoadvisor.com ✉️ info@torqueautoadvisor.com GST No. 24ALBPL1123D1ZY IRDA Code: 1980390000 MSME: UDYAM-GJ-32-0014559 📍 Office Location: https://share.google/IdNJCnrf2jFCWten6
A11: ANJALI-8141489538 | B11: GJ36W1127 | C11: LALJIBHAI DETROJA | D11: 46024 | E11: 995 | F11: 45352 | G11: 9316026698 | H11: ="💬 *TORQUE AUTO ADVISOR – FITNESS / PASSING REMINDER* " & CHAR(10) & "📍 *Morbi*" & CHAR(10) & CHAR(10) & "🧾 *શ્રી " & C11 & " sir*, તમારી ગાડી *" & B11 & "* નું *પાસિંગ (Fitness) તા. " & TEXT(D11,"DD-MM-yyyy") & "* એ પૂરું થાય છે." & CHAR(10) & CHAR(10) & "⚠️ પાસિંગ સમયસર ન કરાવવાથી ઓનલાઇન મેમો આવી શકે છે. કૃપા કરીને પાસિંગ નિયમિત રીતે કરાવજો.પાસિંગ ચાલુ ના હોય તો વીમા ક્લેમ પાસ થતો નથી." & CHAR(10) & CHAR(10) & "✅ અમારી પાસે પાસિંગ, પરમીટ, લાઇસન્સ, નામ ટ્રાન્સફર, વીમો વગેરે RTO ને લગતી તમામ સર્વિસ ઉપલબ્ધ છે. —" & CHAR(10) & "📞 સંપર્ક કરો: " & A11 & " | 8141488962" & CHAR(10) & CHAR(10) & "🏢 *ટોર્ક ઓટો એડવાઇઝર*" & CHAR(10) & "બીજા માળે, જીલ કોમ્પલેક્સ, અયોધ્યાપૂરી રોડ," & CHAR(10) & "જૂના બસ સ્ટેન્ડ પાસે, મોરબી" & CHAR(10) & CHAR(10) & "🌐 www.torqueautoadvisor.com" & CHAR(10) & "✉️ info@torqueautoadvisor.com" & CHAR(10) & CHAR(10) & "GST No. 24ALBPL1123D1ZY" & CHAR(10) & "IRDA Code: 1980390000" & CHAR(10) & "MSME: UDYAM-GJ-32-0014559"& CHAR(10) & CHAR(10) & "📍 Office Location: https://share.google/IdNJCnrf2jFCWten6" -> 💬 *TORQUE AUTO ADVISOR – FITNESS / PASSING REMINDER* 📍 *Morbi* 🧾 *શ્રી LALJIBHAI DETROJA sir*, તમારી ગાડી *GJ36W1127* નું *પાસિંગ (Fitness) તા. 02-01-2026* એ પૂરું થાય છે. ⚠️ પાસિંગ સમયસર ન કરાવવાથી ઓનલાઇન મેમો આવી શકે છે. કૃપા કરીને પાસિંગ નિયમિત રીતે કરાવજો.પાસિંગ ચાલુ ના હોય તો વીમા ક્લેમ પાસ થતો નથી. ✅ અમારી પાસે પાસિંગ, પરમીટ, લાઇસન્સ, નામ ટ્રાન્સફર, વીમો વગેરે RTO ને લગતી તમામ સર્વિસ ઉપલબ્ધ છે. — 📞 સંપર્ક કરો: ANJALI-8141489538 | 8141488962 🏢 *ટોર્ક ઓટો એડવાઇઝર* બીજા માળે, જીલ કોમ્પલેક્સ, અયોધ્યાપૂરી રોડ, જૂના બસ સ્ટેન્ડ પાસે, મોરબી 🌐 www.torqueautoadvisor.com ✉️ info@torqueautoadvisor.com GST No. 24ALBPL1123D1ZY IRDA Code: 1980390000 MSME: UDYAM-GJ-32-0014559 📍 Office Location: https://share.google/IdNJCnrf2jFCWten6
A12: ANJALI-8141489538 | B12: GJ13AT2871 | C12: BHATTI ASHIF | D12: 46024 | E12: 2400 | F12: 18/10/13 | G12: 9638325890 | H12: ="💬 *TORQUE AUTO ADVISOR – FITNESS / PASSING REMINDER* " & CHAR(10) & "📍 *Morbi*" & CHAR(10) & CHAR(10) & "🧾 *શ્રી " & C12 & " sir*, તમારી ગાડી *" & B12 & "* નું *પાસિંગ (Fitness) તા. " & TEXT(D12,"DD-MM-yyyy") & "* એ પૂરું થાય છે." & CHAR(10) & CHAR(10) & "⚠️ પાસિંગ સમયસર ન કરાવવાથી ઓનલાઇન મેમો આવી શકે છે. કૃપા કરીને પાસિંગ નિયમિત રીતે કરાવજો.પાસિંગ ચાલુ ના હોય તો વીમા ક્લેમ પાસ થતો નથી." & CHAR(10) & CHAR(10) & "✅ અમારી પાસે પાસિંગ, પરમીટ, લાઇસન્સ, નામ ટ્રાન્સફર, વીમો વગેરે RTO ને લગતી તમામ સર્વિસ ઉપલબ્ધ છે. —" & CHAR(10) & "📞 સંપર્ક કરો: " & A12 & " | 8141488962" & CHAR(10) & CHAR(10) & "🏢 *ટોર્ક ઓટો એડવાઇઝર*" & CHAR(10) & "બીજા માળે, જીલ કોમ્પલેક્સ, અયોધ્યાપૂરી રોડ," & CHAR(10) & "જૂના બસ સ્ટેન્ડ પાસે, મોરબી" & CHAR(10) & CHAR(10) & "🌐 www.torqueautoadvisor.com" & CHAR(10) & "✉️ info@torqueautoadvisor.com" & CHAR(10) & CHAR(10) & "GST No. 24ALBPL1123D1ZY" & CHAR(10) & "IRDA Code: 1980390000" & CHAR(10) & "MSME: UDYAM-GJ-32-0014559"& CHAR(10) & CHAR(10) & "📍 Office Location: https://share.google/IdNJCnrf2jFCWten6" -> 💬 *TORQUE AUTO ADVISOR – FITNESS / PASSING REMINDER* 📍 *Morbi* 🧾 *શ્રી BHATTI ASHIF sir*, તમારી ગાડી *GJ13AT2871* નું *પાસિંગ (Fitness) તા. 02-01-2026* એ પૂરું થાય છે. ⚠️ પાસિંગ સમયસર ન કરાવવાથી ઓનલાઇન મેમો આવી શકે છે. કૃપા કરીને પાસિંગ નિયમિત રીતે કરાવજો.પાસિંગ ચાલુ ના હોય તો વીમા ક્લેમ પાસ થતો નથી. ✅ અમારી પાસે પાસિંગ, પરમીટ, લાઇસન્સ, નામ ટ્રાન્સફર, વીમો વગેરે RTO ને લગતી તમામ સર્વિસ ઉપલબ્ધ છે. — 📞 સંપર્ક કરો: ANJALI-8141489538 | 8141488962 🏢 *ટોર્ક ઓટો એડવાઇઝર* બીજા માળે, જીલ કોમ્પલેક્સ, અયોધ્યાપૂરી રોડ, જૂના બસ સ્ટેન્ડ પાસે, મોરબી 🌐 www.torqueautoadvisor.com ✉️ info@torqueautoadvisor.com GST No. 24ALBPL1123D1ZY IRDA Code: 1980390000 MSME: UDYAM-GJ-32-0014559 📍 Office Location: https://share.google/IdNJCnrf2jFCWten6
A13: ANJALI-8141489538 | B13: GJ33T2663 | C13: DANGROCHA BHANJIBHAI VAGHAJIBHAI | D13: 46024 | E13: 35000 | F13: 40522 | G13: 9727364709 | H13: ="💬 *TORQUE AUTO ADVISOR – FITNESS / PASSING REMINDER* " & CHAR(10) & "📍 *Morbi*" & CHAR(10) & CHAR(10) & "🧾 *શ્રી " & C13 & " sir*, તમારી ગાડી *" & B13 & "* નું *પાસિંગ (Fitness) તા. " & TEXT(D13,"DD-MM-yyyy") & "* એ પૂરું થાય છે." & CHAR(10) & CHAR(10) & "⚠️ પાસિંગ સમયસર ન કરાવવાથી ઓનલાઇન મેમો આવી શકે છે. કૃપા કરીને પાસિંગ નિયમિત રીતે કરાવજો.પાસિંગ ચાલુ ના હોય તો વીમા ક્લેમ પાસ થતો નથી." & CHAR(10) & CHAR(10) & "✅ અમારી પાસે પાસિંગ, પરમીટ, લાઇસન્સ, નામ ટ્રાન્સફર, વીમો વગેરે RTO ને લગતી તમામ સર્વિસ ઉપલબ્ધ છે. —" & CHAR(10) & "📞 સંપર્ક કરો: " & A13 & " | 8141488962" & CHAR(10) & CHAR(10) & "🏢 *ટોર્ક ઓટો એડવાઇઝર*" & CHAR(10) & "બીજા માળે, જીલ કોમ્પલેક્સ, અયોધ્યાપૂરી રોડ," & CHAR(10) & "જૂના બસ સ્ટેન્ડ પાસે, મોરબી" & CHAR(10) & CHAR(10) & "🌐 www.torqueautoadvisor.com" & CHAR(10) & "✉️ info@torqueautoadvisor.com" & CHAR(10) & CHAR(10) & "GST No. 24ALBPL1123D1ZY" & CHAR(10) & "IRDA Code: 1980390000" & CHAR(10) & "MSME: UDYAM-GJ-32-0014559"& CHAR(10) & CHAR(10) & "📍 Office Location: https://share.google/IdNJCnrf2jFCWten6" -> 💬 *TORQUE AUTO ADVISOR – FITNESS / PASSING REMINDER* 📍 *Morbi* 🧾 *શ્રી DANGROCHA BHANJIBHAI VAGHAJIBHAI sir*, તમારી ગાડી *GJ33T2663* નું *પાસિંગ (Fitness) તા. 02-01-2026* એ પૂરું થાય છે. ⚠️ પાસિંગ સમયસર ન કરાવવાથી ઓનલાઇન મેમો આવી શકે છે. કૃપા કરીને પાસિંગ નિયમિત રીતે કરાવજો.પાસિંગ ચાલુ ના હોય તો વીમા ક્લેમ પાસ થતો નથી. ✅ અમારી પાસે પાસિંગ, પરમીટ, લાઇસન્સ, નામ ટ્રાન્સફર, વીમો વગેરે RTO ને લગતી તમામ સર્વિસ ઉપલબ્ધ છે. — 📞 સંપર્ક કરો: ANJALI-8141489538 | 8141488962 🏢 *ટોર્ક ઓટો એડવાઇઝર* બીજા માળે, જીલ કોમ્પલેક્સ, અયોધ્યાપૂરી રોડ, જૂના બસ સ્ટેન્ડ પાસે, મોરબી 🌐 www.torqueautoadvisor.com ✉️ info@torqueautoadvisor.com GST No. 24ALBPL1123D1ZY IRDA Code: 1980390000 MSME: UDYAM-GJ-32-0014559 📍 Office Location: https://share.google/IdNJCnrf2jFCWten6
A14: ANJALI-8141489538 | B14: GJ11X9163 | C14: GARCHAR RAMABHAI LAKHMANBHAI | D14: 46024 | E14: 18500 | F14: 15/09/06 | G14: 9879024612 | H14: ="💬 *TORQUE AUTO ADVISOR – FITNESS / PASSING REMINDER* " & CHAR(10) & "📍 *Morbi*" & CHAR(10) & CHAR(10) & "🧾 *શ્રી " & C14 & " sir*, તમારી ગાડી *" & B14 & "* નું *પાસિંગ (Fitness) તા. " & TEXT(D14,"DD-MM-yyyy") & "* એ પૂરું થાય છે." & CHAR(10) & CHAR(10) & "⚠️ પાસિંગ સમયસર ન કરાવવાથી ઓનલાઇન મેમો આવી શકે છે. કૃપા કરીને પાસિંગ નિયમિત રીતે કરાવજો.પાસિંગ ચાલુ ના હોય તો વીમા ક્લેમ પાસ થતો નથી." & CHAR(10) & CHAR(10) & "✅ અમારી પાસે પાસિંગ, પરમીટ, લાઇસન્સ, નામ ટ્રાન્સફર, વીમો વગેરે RTO ને લગતી તમામ સર્વિસ ઉપલબ્ધ છે. —" & CHAR(10) & "📞 સંપર્ક કરો: " & A14 & " | 8141488962" & CHAR(10) & CHAR(10) & "🏢 *ટોર્ક ઓટો એડવાઇઝર*" & CHAR(10) & "બીજા માળે, જીલ કોમ્પલેક્સ, અયોધ્યાપૂરી રોડ," & CHAR(10) & "જૂના બસ સ્ટેન્ડ પાસે, મોરબી" & CHAR(10) & CHAR(10) & "🌐 www.torqueautoadvisor.com" & CHAR(10) & "✉️ info@torqueautoadvisor.com" & CHAR(10) & CHAR(10) & "GST No. 24ALBPL1123D1ZY" & CHAR(10) & "IRDA Code: 1980390000" & CHAR(10) & "MSME: UDYAM-GJ-32-0014559"& CHAR(10) & CHAR(10) & "📍 Office Location: https://share.google/IdNJCnrf2jFCWten6" -> 💬 *TORQUE AUTO ADVISOR – FITNESS / PASSING REMINDER* 📍 *Morbi* 🧾 *શ્રી GARCHAR RAMABHAI LAKHMANBHAI sir*, તમારી ગાડી *GJ11X9163* નું *પાસિંગ (Fitness) તા. 02-01-2026* એ પૂરું થાય છે. ⚠️ પાસિંગ સમયસર ન કરાવવાથી ઓનલાઇન મેમો આવી શકે છે. કૃપા કરીને પાસિંગ નિયમિત રીતે કરાવજો.પાસિંગ ચાલુ ના હોય તો વીમા ક્લેમ પાસ થતો નથી. ✅ અમારી પાસે પાસિંગ, પરમીટ, લાઇસન્સ, નામ ટ્રાન્સફર, વીમો વગેરે RTO ને લગતી તમામ સર્વિસ ઉપલબ્ધ છે. — 📞 સંપર્ક કરો: ANJALI-8141489538 | 8141488962 🏢 *ટોર્ક ઓટો એડવાઇઝર* બીજા માળે, જીલ કોમ્પલેક્સ, અયોધ્યાપૂરી રોડ, જૂના બસ સ્ટેન્ડ પાસે, મોરબી 🌐 www.torqueautoadvisor.com ✉️ info@torqueautoadvisor.com GST No. 24ALBPL1123D1ZY IRDA Code: 1980390000 MSME: UDYAM-GJ-32-0014559 📍 Office Location: https://share.google/IdNJCnrf2jFCWten6
A15: ANJALI-8141489538 | B15: GJ36X4488 | C15: RAJENDRASINH | D15: 46024 | E15: 17750 | F15: 45352 | G15: 9909068088 | H15: ="💬 *TORQUE AUTO ADVISOR – FITNESS / PASSING REMINDER* " & CHAR(10) & "📍 *Morbi*" & CHAR(10) & CHAR(10) & "🧾 *શ્રી " & C15 & " sir*, તમારી ગાડી *" & B15 & "* નું *પાસિંગ (Fitness) તા. " & TEXT(D15,"DD-MM-yyyy") & "* એ પૂરું થાય છે." & CHAR(10) & CHAR(10) & "⚠️ પાસિંગ સમયસર ન કરાવવાથી ઓનલાઇન મેમો આવી શકે છે. કૃપા કરીને પાસિંગ નિયમિત રીતે કરાવજો.પાસિંગ ચાલુ ના હોય તો વીમા ક્લેમ પાસ થતો નથી." & CHAR(10) & CHAR(10) & "✅ અમારી પાસે પાસિંગ, પરમીટ, લાઇસન્સ, નામ ટ્રાન્સફર, વીમો વગેરે RTO ને લગતી તમામ સર્વિસ ઉપલબ્ધ છે. —" & CHAR(10) & "📞 સંપર્ક કરો: " & A15 & " | 8141488962" & CHAR(10) & CHAR(10) & "🏢 *ટોર્ક ઓટો એડવાઇઝર*" & CHAR(10) & "બીજા માળે, જીલ કોમ્પલેક્સ, અયોધ્યાપૂરી રોડ," & CHAR(10) & "જૂના બસ સ્ટેન્ડ પાસે, મોરબી" & CHAR(10) & CHAR(10) & "🌐 www.torqueautoadvisor.com" & CHAR(10) & "✉️ info@torqueautoadvisor.com" & CHAR(10) & CHAR(10) & "GST No. 24ALBPL1123D1ZY" & CHAR(10) & "IRDA Code: 1980390000" & CHAR(10) & "MSME: UDYAM-GJ-32-0014559"& CHAR(10) & CHAR(10) & "📍 Office Location: https://share.google/IdNJCnrf2jFCWten6" -> 💬 *TORQUE AUTO ADVISOR – FITNESS / PASSING REMINDER* 📍 *Morbi* 🧾 *શ્રી RAJENDRASINH sir*, તમારી ગાડી *GJ36X4488* નું *પાસિંગ (Fitness) તા. 02-01-2026* એ પૂરું થાય છે. ⚠️ પાસિંગ સમયસર ન કરાવવાથી ઓનલાઇન મેમો આવી શકે છે. કૃપા કરીને પાસિંગ નિયમિત રીતે કરાવજો.પાસિંગ ચાલુ ના હોય તો વીમા ક્લેમ પાસ થતો નથી. ✅ અમારી પાસે પાસિંગ, પરમીટ, લાઇસન્સ, નામ ટ્રાન્સફર, વીમો વગેરે RTO ને લગતી તમામ સર્વિસ ઉપલબ્ધ છે. — 📞 સંપર્ક કરો: ANJALI-8141489538 | 8141488962 🏢 *ટોર્ક ઓટો એડવાઇઝર* બીજા માળે, જીલ કોમ્પલેક્સ, અયોધ્યાપૂરી રોડ, જૂના બસ સ્ટેન્ડ પાસે, મોરબી 🌐 www.torqueautoadvisor.com ✉️ info@torqueautoadvisor.com GST No. 24ALBPL1123D1ZY IRDA Code: 1980390000 MSME: UDYAM-GJ-32-0014559 📍 Office Location: https://share.google/IdNJCnrf2jFCWten6
A16: ANJALI-8141489538 | B16: GJ36W9229 | C16: KURESHI ASIF | D16: 46024 | E16: 818 | F16: 45352 | G16: 9974580560 | H16: ="💬 *TORQUE AUTO ADVISOR – FITNESS / PASSING REMINDER* " & CHAR(10) & "📍 *Morbi*" & CHAR(10) & CHAR(10) & "🧾 *શ્રી " & C16 & " sir*, તમારી ગાડી *" & B16 & "* નું *પાસિંગ (Fitness) તા. " & TEXT(D16,"DD-MM-yyyy") & "* એ પૂરું થાય છે." & CHAR(10) & CHAR(10) & "⚠️ પાસિંગ સમયસર ન કરાવવાથી ઓનલાઇન મેમો આવી શકે છે. કૃપા કરીને પાસિંગ નિયમિત રીતે કરાવજો.પાસિંગ ચાલુ ના હોય તો વીમા ક્લેમ પાસ થતો નથી." & CHAR(10) & CHAR(10) & "✅ અમારી પાસે પાસિંગ, પરમીટ, લાઇસન્સ, નામ ટ્રાન્સફર, વીમો વગેરે RTO ને લગતી તમામ સર્વિસ ઉપલબ્ધ છે. —" & CHAR(10) & "📞 સંપર્ક કરો: " & A16 & " | 8141488962" & CHAR(10) & CHAR(10) & "🏢 *ટોર્ક ઓટો એડવાઇઝર*" & CHAR(10) & "બીજા માળે, જીલ કોમ્પલેક્સ, અયોધ્યાપૂરી રોડ," & CHAR(10) & "જૂના બસ સ્ટેન્ડ પાસે, મોરબી" & CHAR(10) & CHAR(10) & "🌐 www.torqueautoadvisor.com" & CHAR(10) & "✉️ info@torqueautoadvisor.com" & CHAR(10) & CHAR(10) & "GST No. 24ALBPL1123D1ZY" & CHAR(10) & "IRDA Code: 1980390000" & CHAR(10) & "MSME: UDYAM-GJ-32-0014559"& CHAR(10) & CHAR(10) & "📍 Office Location: https://share.google/IdNJCnrf2jFCWten6" -> 💬 *TORQUE AUTO ADVISOR – FITNESS / PASSING REMINDER* 📍 *Morbi* 🧾 *શ્રી KURESHI ASIF sir*, તમારી ગાડી *GJ36W9229* નું *પાસિંગ (Fitness) તા. 02-01-2026* એ પૂરું થાય છે. ⚠️ પાસિંગ સમયસર ન કરાવવાથી ઓનલાઇન મેમો આવી શકે છે. કૃપા કરીને પાસિંગ નિયમિત રીતે કરાવજો.પાસિંગ ચાલુ ના હોય તો વીમા ક્લેમ પાસ થતો નથી. ✅ અમારી પાસે પાસિંગ, પરમીટ, લાઇસન્સ, નામ ટ્રાન્સફર, વીમો વગેરે RTO ને લગતી તમામ સર્વિસ ઉપલબ્ધ છે. — 📞 સંપર્ક કરો: ANJALI-8141489538 | 8141488962 🏢 *ટોર્ક ઓટો એડવાઇઝર* બીજા માળે, જીલ કોમ્પલેક્સ, અયોધ્યાપૂરી રોડ, જૂના બસ સ્ટેન્ડ પાસે, મોરબી 🌐 www.torqueautoadvisor.com ✉️ info@torqueautoadvisor.com GST No. 24ALBPL1123D1ZY IRDA Code: 1980390000 MSME: UDYAM-GJ-32-0014559 📍 Office Location: https://share.google/IdNJCnrf2jFCWten6
A17: ANJALI-8141489538 | B17: GJ08AW4790 | C17: KALPESHKUMAR RAMESHBHAI KARPATIYA | D17: 46025 | E17: 17750 | F17: 45383 | G17: 6355820313 | H17: ="💬 *TORQUE AUTO ADVISOR – FITNESS / PASSING REMINDER* " & CHAR(10) & "📍 *Morbi*" & CHAR(10) & CHAR(10) & "🧾 *શ્રી " & C17 & " sir*, તમારી ગાડી *" & B17 & "* નું *પાસિંગ (Fitness) તા. " & TEXT(D17,"DD-MM-yyyy") & "* એ પૂરું થાય છે." & CHAR(10) & CHAR(10) & "⚠️ પાસિંગ સમયસર ન કરાવવાથી ઓનલાઇન મેમો આવી શકે છે. કૃપા કરીને પાસિંગ નિયમિત રીતે કરાવજો.પાસિંગ ચાલુ ના હોય તો વીમા ક્લેમ પાસ થતો નથી." & CHAR(10) & CHAR(10) & "✅ અમારી પાસે પાસિંગ, પરમીટ, લાઇસન્સ, નામ ટ્રાન્સફર, વીમો વગેરે RTO ને લગતી તમામ સર્વિસ ઉપલબ્ધ છે. —" & CHAR(10) & "📞 સંપર્ક કરો: " & A17 & " | 8141488962" & CHAR(10) & CHAR(10) & "🏢 *ટોર્ક ઓટો એડવાઇઝર*" & CHAR(10) & "બીજા માળે, જીલ કોમ્પલેક્સ, અયોધ્યાપૂરી રોડ," & CHAR(10) & "જૂના બસ સ્ટેન્ડ પાસે, મોરબી" & CHAR(10) & CHAR(10) & "🌐 www.torqueautoadvisor.com" & CHAR(10) & "✉️ info@torqueautoadvisor.com" & CHAR(10) & CHAR(10) & "GST No. 24ALBPL1123D1ZY" & CHAR(10) & "IRDA Code: 1980390000" & CHAR(10) & "MSME: UDYAM-GJ-32-0014559"& CHAR(10) & CHAR(10) & "📍 Office Location: https://share.google/IdNJCnrf2jFCWten6" -> 💬 *TORQUE AUTO ADVISOR – FITNESS / PASSING REMINDER* 📍 *Morbi* 🧾 *શ્રી KALPESHKUMAR RAMESHBHAI KARPATIYA sir*, તમારી ગાડી *GJ08AW4790* નું *પાસિંગ (Fitness) તા. 03-01-2026* એ પૂરું થાય છે. ⚠️ પાસિંગ સમયસર ન કરાવવાથી ઓનલાઇન મેમો આવી શકે છે. કૃપા કરીને પાસિંગ નિયમિત રીતે કરાવજો.પાસિંગ ચાલુ ના હોય તો વીમા ક્લેમ પાસ થતો નથી. ✅ અમારી પાસે પાસિંગ, પરમીટ, લાઇસન્સ, નામ ટ્રાન્સફર, વીમો વગેરે RTO ને લગતી તમામ સર્વિસ ઉપલબ્ધ છે. — 📞 સંપર્ક કરો: ANJALI-8141489538 | 8141488962 🏢 *ટોર્ક ઓટો એડવાઇઝર* બીજા માળે, જીલ કોમ્પલેક્સ, અયોધ્યાપૂરી રોડ, જૂના બસ સ્ટેન્ડ પાસે, મોરબી 🌐 www.torqueautoadvisor.com ✉️ info@torqueautoadvisor.com GST No. 24ALBPL1123D1ZY IRDA Code: 1980390000 MSME: UDYAM-GJ-32-0014559 📍 Office Location: https://share.google/IdNJCnrf2jFCWten6
A18: ANJALI-8141489538 | B18: GJ03BZ1676 | C18: RAVI SOLANKI | D18: 46025 | E18: 1600 | F18: 45383 | G18: 8141402138 | H18: ="💬 *TORQUE AUTO ADVISOR – FITNESS / PASSING REMINDER* " & CHAR(10) & "📍 *Morbi*" & CHAR(10) & CHAR(10) & "🧾 *શ્રી " & C18 & " sir*, તમારી ગાડી *" & B18 & "* નું *પાસિંગ (Fitness) તા. " & TEXT(D18,"DD-MM-yyyy") & "* એ પૂરું થાય છે." & CHAR(10) & CHAR(10) & "⚠️ પાસિંગ સમયસર ન કરાવવાથી ઓનલાઇન મેમો આવી શકે છે. કૃપા કરીને પાસિંગ નિયમિત રીતે કરાવજો.પાસિંગ ચાલુ ના હોય તો વીમા ક્લેમ પાસ થતો નથી." & CHAR(10) & CHAR(10) & "✅ અમારી પાસે પાસિંગ, પરમીટ, લાઇસન્સ, નામ ટ્રાન્સફર, વીમો વગેરે RTO ને લગતી તમામ સર્વિસ ઉપલબ્ધ છે. —" & CHAR(10) & "📞 સંપર્ક કરો: " & A18 & " | 8141488962" & CHAR(10) & CHAR(10) & "🏢 *ટોર્ક ઓટો એડવાઇઝર*" & CHAR(10) & "બીજા માળે, જીલ કોમ્પલેક્સ, અયોધ્યાપૂરી રોડ," & CHAR(10) & "જૂના બસ સ્ટેન્ડ પાસે, મોરબી" & CHAR(10) & CHAR(10) & "🌐 www.torqueautoadvisor.com" & CHAR(10) & "✉️ info@torqueautoadvisor.com" & CHAR(10) & CHAR(10) & "GST No. 24ALBPL1123D1ZY" & CHAR(10) & "IRDA Code: 1980390000" & CHAR(10) & "MSME: UDYAM-GJ-32-0014559"& CHAR(10) & CHAR(10) & "📍 Office Location: https://share.google/IdNJCnrf2jFCWten6" -> 💬 *TORQUE AUTO ADVISOR – FITNESS / PASSING REMINDER* 📍 *Morbi* 🧾 *શ્રી RAVI SOLANKI sir*, તમારી ગાડી *GJ03BZ1676* નું *પાસિંગ (Fitness) તા. 03-01-2026* એ પૂરું થાય છે. ⚠️ પાસિંગ સમયસર ન કરાવવાથી ઓનલાઇન મેમો આવી શકે છે. કૃપા કરીને પાસિંગ નિયમિત રીતે કરાવજો.પાસિંગ ચાલુ ના હોય તો વીમા ક્લેમ પાસ થતો નથી. ✅ અમારી પાસે પાસિંગ, પરમીટ, લાઇસન્સ, નામ ટ્રાન્સફર, વીમો વગેરે RTO ને લગતી તમામ સર્વિસ ઉપલબ્ધ છે. — 📞 સંપર્ક કરો: ANJALI-8141489538 | 8141488962 🏢 *ટોર્ક ઓટો એડવાઇઝર* બીજા માળે, જીલ કોમ્પલેક્સ, અયોધ્યાપૂરી રોડ, જૂના બસ સ્ટેન્ડ પાસે, મોરબી 🌐 www.torqueautoadvisor.com ✉️ info@torqueautoadvisor.com GST No. 24ALBPL1123D1ZY IRDA Code: 1980390000 MSME: UDYAM-GJ-32-0014559 📍 Office Location: https://share.google/IdNJCnrf2jFCWten6
A19: ANJALI-8141489538 | B19: GJ36T3675 | C19: VISHRAM PATEL | D19: 46025 | E19: 42000 | F19: 43101 | G19: 9039703788 | H19: ="💬 *TORQUE AUTO ADVISOR – FITNESS / PASSING REMINDER* " & CHAR(10) & "📍 *Morbi*" & CHAR(10) & CHAR(10) & "🧾 *શ્રી " & C19 & " sir*, તમારી ગાડી *" & B19 & "* નું *પાસિંગ (Fitness) તા. " & TEXT(D19,"DD-MM-yyyy") & "* એ પૂરું થાય છે." & CHAR(10) & CHAR(10) & "⚠️ પાસિંગ સમયસર ન કરાવવાથી ઓનલાઇન મેમો આવી શકે છે. કૃપા કરીને પાસિંગ નિયમિત રીતે કરાવજો.પાસિંગ ચાલુ ના હોય તો વીમા ક્લેમ પાસ થતો નથી." & CHAR(10) & CHAR(10) & "✅ અમારી પાસે પાસિંગ, પરમીટ, લાઇસન્સ, નામ ટ્રાન્સફર, વીમો વગેરે RTO ને લગતી તમામ સર્વિસ ઉપલબ્ધ છે. —" & CHAR(10) & "📞 સંપર્ક કરો: " & A19 & " | 8141488962" & CHAR(10) & CHAR(10) & "🏢 *ટોર્ક ઓટો એડવાઇઝર*" & CHAR(10) & "બીજા માળે, જીલ કોમ્પલેક્સ, અયોધ્યાપૂરી રોડ," & CHAR(10) & "જૂના બસ સ્ટેન્ડ પાસે, મોરબી" & CHAR(10) & CHAR(10) & "🌐 www.torqueautoadvisor.com" & CHAR(10) & "✉️ info@torqueautoadvisor.com" & CHAR(10) & CHAR(10) & "GST No. 24ALBPL1123D1ZY" & CHAR(10) & "IRDA Code: 1980390000" & CHAR(10) & "MSME: UDYAM-GJ-32-0014559"& CHAR(10) & CHAR(10) & "📍 Office Location: https://share.google/IdNJCnrf2jFCWten6" -> 💬 *TORQUE AUTO ADVISOR – FITNESS / PASSING REMINDER* 📍 *Morbi* 🧾 *શ્રી VISHRAM PATEL sir*, તમારી ગાડી *GJ36T3675* નું *પાસિંગ (Fitness) તા. 03-01-2026* એ પૂરું થાય છે. ⚠️ પાસિંગ સમયસર ન કરાવવાથી ઓનલાઇન મેમો આવી શકે છે. કૃપા કરીને પાસિંગ નિયમિત રીતે કરાવજો.પાસિંગ ચાલુ ના હોય તો વીમા ક્લેમ પાસ થતો નથી. ✅ અમારી પાસે પાસિંગ, પરમીટ, લાઇસન્સ, નામ ટ્રાન્સફર, વીમો વગેરે RTO ને લગતી તમામ સર્વિસ ઉપલબ્ધ છે. — 📞 સંપર્ક કરો: ANJALI-8141489538 | 8141488962 🏢 *ટોર્ક ઓટો એડવાઇઝર* બીજા માળે, જીલ કોમ્પલેક્સ, અયોધ્યાપૂરી રોડ, જૂના બસ સ્ટેન્ડ પાસે, મોરબી 🌐 www.torqueautoadvisor.com ✉️ info@torqueautoadvisor.com GST No. 24ALBPL1123D1ZY IRDA Code: 1980390000 MSME: UDYAM-GJ-32-0014559 📍 Office Location: https://share.google/IdNJCnrf2jFCWten6
A20: ANJALI-8141489538 | B20: GJ36V5816 | C20: VIPUL KUVARJI SOLANKI | D20: 46025 | E20: 1600 | F20: 45383 | G20: 9512278302 | H20: ="💬 *TORQUE AUTO ADVISOR – FITNESS / PASSING REMINDER* " & CHAR(10) & "📍 *Morbi*" & CHAR(10) & CHAR(10) & "🧾 *શ્રી " & C20 & " sir*, તમારી ગાડી *" & B20 & "* નું *પાસિંગ (Fitness) તા. " & TEXT(D20,"DD-MM-yyyy") & "* એ પૂરું થાય છે." & CHAR(10) & CHAR(10) & "⚠️ પાસિંગ સમયસર ન કરાવવાથી ઓનલાઇન મેમો આવી શકે છે. કૃપા કરીને પાસિંગ નિયમિત રીતે કરાવજો.પાસિંગ ચાલુ ના હોય તો વીમા ક્લેમ પાસ થતો નથી." & CHAR(10) & CHAR(10) & "✅ અમારી પાસે પાસિંગ, પરમીટ, લાઇસન્સ, નામ ટ્રાન્સફર, વીમો વગેરે RTO ને લગતી તમામ સર્વિસ ઉપલબ્ધ છે. —" & CHAR(10) & "📞 સંપર્ક કરો: " & A20 & " | 8141488962" & CHAR(10) & CHAR(10) & "🏢 *ટોર્ક ઓટો એડવાઇઝર*" & CHAR(10) & "બીજા માળે, જીલ કોમ્પલેક્સ, અયોધ્યાપૂરી રોડ," & CHAR(10) & "જૂના બસ સ્ટેન્ડ પાસે, મોરબી" & CHAR(10) & CHAR(10) & "🌐 www.torqueautoadvisor.com" & CHAR(10) & "✉️ info@torqueautoadvisor.com" & CHAR(10) & CHAR(10) & "GST No. 24ALBPL1123D1ZY" & CHAR(10) & "IRDA Code: 1980390000" & CHAR(10) & "MSME: UDYAM-GJ-32-0014559"& CHAR(10) & CHAR(10) & "📍 Office Location: https://share.google/IdNJCnrf2jFCWten6" -> 💬 *TORQUE AUTO ADVISOR – FITNESS / PASSING REMINDER* 📍 *Morbi* 🧾 *શ્રી VIPUL KUVARJI SOLANKI sir*, તમારી ગાડી *GJ36V5816* નું *પાસિંગ (Fitness) તા. 03-01-2026* એ પૂરું થાય છે. ⚠️ પાસિંગ સમયસર ન કરાવવાથી ઓનલાઇન મેમો આવી શકે છે. કૃપા કરીને પાસિંગ નિયમિત રીતે કરાવજો.પાસિંગ ચાલુ ના હોય તો વીમા ક્લેમ પાસ થતો નથી. ✅ અમારી પાસે પાસિંગ, પરમીટ, લાઇસન્સ, નામ ટ્રાન્સફર, વીમો વગેરે RTO ને લગતી તમામ સર્વિસ ઉપલબ્ધ છે. — 📞 સંપર્ક કરો: ANJALI-8141489538 | 8141488962 🏢 *ટોર્ક ઓટો એડવાઇઝર* બીજા માળે, જીલ કોમ્પલેક્સ, અયોધ્યાપૂરી રોડ, જૂના બસ સ્ટેન્ડ પાસે, મોરબી 🌐 www.torqueautoadvisor.com ✉️ info@torqueautoadvisor.com GST No. 24ALBPL1123D1ZY IRDA Code: 1980390000 MSME: UDYAM-GJ-32-0014559 📍 Office Location: https://share.google/IdNJCnrf2jFCWten6
A21: ANJALI-8141489538 | B21: GJ36V6423 | C21: DIPAK PATADIYA | D21: 46025 | E21: 1600 | F21: 45383 | G21: 9773085410 | H21: ="💬 *TORQUE AUTO ADVISOR – FITNESS / PASSING REMINDER* " & CHAR(10) & "📍 *Morbi*" & CHAR(10) & CHAR(10) & "🧾 *શ્રી " & C21 & " sir*, તમારી ગાડી *" & B21 & "* નું *પાસિંગ (Fitness) તા. " & TEXT(D21,"DD-MM-yyyy") & "* એ પૂરું થાય છે." & CHAR(10) & CHAR(10) & "⚠️ પાસિંગ સમયસર ન કરાવવાથી ઓનલાઇન મેમો આવી શકે છે. કૃપા કરીને પાસિંગ નિયમિત રીતે કરાવજો.પાસિંગ ચાલુ ના હોય તો વીમા ક્લેમ પાસ થતો નથી." & CHAR(10) & CHAR(10) & "✅ અમારી પાસે પાસિંગ, પરમીટ, લાઇસન્સ, નામ ટ્રાન્સફર, વીમો વગેરે RTO ને લગતી તમામ સર્વિસ ઉપલબ્ધ છે. —" & CHAR(10) & "📞 સંપર્ક કરો: " & A21 & " | 8141488962" & CHAR(10) & CHAR(10) & "🏢 *ટોર્ક ઓટો એડવાઇઝર*" & CHAR(10) & "બીજા માળે, જીલ કોમ્પલેક્સ, અયોધ્યાપૂરી રોડ," & CHAR(10) & "જૂના બસ સ્ટેન્ડ પાસે, મોરબી" & CHAR(10) & CHAR(10) & "🌐 www.torqueautoadvisor.com" & CHAR(10) & "✉️ info@torqueautoadvisor.com" & CHAR(10) & CHAR(10) & "GST No. 24ALBPL1123D1ZY" & CHAR(10) & "IRDA Code: 1980390000" & CHAR(10) & "MSME: UDYAM-GJ-32-0014559"& CHAR(10) & CHAR(10) & "📍 Office Location: https://share.google/IdNJCnrf2jFCWten6" -> 💬 *TORQUE AUTO ADVISOR – FITNESS / PASSING REMINDER* 📍 *Morbi* 🧾 *શ્રી DIPAK PATADIYA sir*, તમારી ગાડી *GJ36V6423* નું *પાસિંગ (Fitness) તા. 03-01-2026* એ પૂરું થાય છે. ⚠️ પાસિંગ સમયસર ન કરાવવાથી ઓનલાઇન મેમો આવી શકે છે. કૃપા કરીને પાસિંગ નિયમિત રીતે કરાવજો.પાસિંગ ચાલુ ના હોય તો વીમા ક્લેમ પાસ થતો નથી. ✅ અમારી પાસે પાસિંગ, પરમીટ, લાઇસન્સ, નામ ટ્રાન્સફર, વીમો વગેરે RTO ને લગતી તમામ સર્વિસ ઉપલબ્ધ છે. — 📞 સંપર્ક કરો: ANJALI-8141489538 | 8141488962 🏢 *ટોર્ક ઓટો એડવાઇઝર* બીજા માળે, જીલ કોમ્પલેક્સ, અયોધ્યાપૂરી રોડ, જૂના બસ સ્ટેન્ડ પાસે, મોરબી 🌐 www.torqueautoadvisor.com ✉️ info@torqueautoadvisor.com GST No. 24ALBPL1123D1ZY IRDA Code: 1980390000 MSME: UDYAM-GJ-32-0014559 📍 Office Location: https://share.google/IdNJCnrf2jFCWten6
A22: ANJALI-8141489538 | B22: GJ12X1694 | C22: GARCHAR NARANBHAI LAKHMANBHAI | D22: 46025 | E22: 18500 | F22: 38508 | G22: 9879024612 | H22: ="💬 *TORQUE AUTO ADVISOR – FITNESS / PASSING REMINDER* " & CHAR(10) & "📍 *Morbi*" & CHAR(10) & CHAR(10) & "🧾 *શ્રી " & C22 & " sir*, તમારી ગાડી *" & B22 & "* નું *પાસિંગ (Fitness) તા. " & TEXT(D22,"DD-MM-yyyy") & "* એ પૂરું થાય છે." & CHAR(10) & CHAR(10) & "⚠️ પાસિંગ સમયસર ન કરાવવાથી ઓનલાઇન મેમો આવી શકે છે. કૃપા કરીને પાસિંગ નિયમિત રીતે કરાવજો.પાસિંગ ચાલુ ના હોય તો વીમા ક્લેમ પાસ થતો નથી." & CHAR(10) & CHAR(10) & "✅ અમારી પાસે પાસિંગ, પરમીટ, લાઇસન્સ, નામ ટ્રાન્સફર, વીમો વગેરે RTO ને લગતી તમામ સર્વિસ ઉપલબ્ધ છે. —" & CHAR(10) & "📞 સંપર્ક કરો: " & A22 & " | 8141488962" & CHAR(10) & CHAR(10) & "🏢 *ટોર્ક ઓટો એડવાઇઝર*" & CHAR(10) & "બીજા માળે, જીલ કોમ્પલેક્સ, અયોધ્યાપૂરી રોડ," & CHAR(10) & "જૂના બસ સ્ટેન્ડ પાસે, મોરબી" & CHAR(10) & CHAR(10) & "🌐 www.torqueautoadvisor.com" & CHAR(10) & "✉️ info@torqueautoadvisor.com" & CHAR(10) & CHAR(10) & "GST No. 24ALBPL1123D1ZY" & CHAR(10) & "IRDA Code: 1980390000" & CHAR(10) & "MSME: UDYAM-GJ-32-0014559"& CHAR(10) & CHAR(10) & "📍 Office Location: https://share.google/IdNJCnrf2jFCWten6" -> 💬 *TORQUE AUTO ADVISOR – FITNESS / PASSING REMINDER* 📍 *Morbi* 🧾 *શ્રી GARCHAR NARANBHAI LAKHMANBHAI sir*, તમારી ગાડી *GJ12X1694* નું *પાસિંગ (Fitness) તા. 03-01-2026* એ પૂરું થાય છે. ⚠️ પાસિંગ સમયસર ન કરાવવાથી ઓનલાઇન મેમો આવી શકે છે. કૃપા કરીને પાસિંગ નિયમિત રીતે કરાવજો.પાસિંગ ચાલુ ના હોય તો વીમા ક્લેમ પાસ થતો નથી. ✅ અમારી પાસે પાસિંગ, પરમીટ, લાઇસન્સ, નામ ટ્રાન્સફર, વીમો વગેરે RTO ને લગતી તમામ સર્વિસ ઉપલબ્ધ છે. — 📞 સંપર્ક કરો: ANJALI-8141489538 | 8141488962 🏢 *ટોર્ક ઓટો એડવાઇઝર* બીજા માળે, જીલ કોમ્પલેક્સ, અયોધ્યાપૂરી રોડ, જૂના બસ સ્ટેન્ડ પાસે, મોરબી 🌐 www.torqueautoadvisor.com ✉️ info@torqueautoadvisor.com GST No. 24ALBPL1123D1ZY IRDA Code: 1980390000 MSME: UDYAM-GJ-32-0014559 📍 Office Location: https://share.google/IdNJCnrf2jFCWten6
A23: ANJALI-8141489538 | B23: GJ36S2655 | C23: FUSION GRANITO PVT LTD | D23: 46025 | E23: 0 | F23: 44682 | G23: 9909173071 | H23: ="💬 *TORQUE AUTO ADVISOR – FITNESS / PASSING REMINDER* " & CHAR(10) & "📍 *Morbi*" & CHAR(10) & CHAR(10) & "🧾 *શ્રી " & C23 & " sir*, તમારી ગાડી *" & B23 & "* નું *પાસિંગ (Fitness) તા. " & TEXT(D23,"DD-MM-yyyy") & "* એ પૂરું થાય છે." & CHAR(10) & CHAR(10) & "⚠️ પાસિંગ સમયસર ન કરાવવાથી ઓનલાઇન મેમો આવી શકે છે. કૃપા કરીને પાસિંગ નિયમિત રીતે કરાવજો.પાસિંગ ચાલુ ના હોય તો વીમા ક્લેમ પાસ થતો નથી." & CHAR(10) & CHAR(10) & "✅ અમારી પાસે પાસિંગ, પરમીટ, લાઇસન્સ, નામ ટ્રાન્સફર, વીમો વગેરે RTO ને લગતી તમામ સર્વિસ ઉપલબ્ધ છે. —" & CHAR(10) & "📞 સંપર્ક કરો: " & A23 & " | 8141488962" & CHAR(10) & CHAR(10) & "🏢 *ટોર્ક ઓટો એડવાઇઝર*" & CHAR(10) & "બીજા માળે, જીલ કોમ્પલેક્સ, અયોધ્યાપૂરી રોડ," & CHAR(10) & "જૂના બસ સ્ટેન્ડ પાસે, મોરબી" & CHAR(10) & CHAR(10) & "🌐 www.torqueautoadvisor.com" & CHAR(10) & "✉️ info@torqueautoadvisor.com" & CHAR(10) & CHAR(10) & "GST No. 24ALBPL1123D1ZY" & CHAR(10) & "IRDA Code: 1980390000" & CHAR(10) & "MSME: UDYAM-GJ-32-0014559"& CHAR(10) & CHAR(10) & "📍 Office Location: https://share.google/IdNJCnrf2jFCWten6" -> 💬 *TORQUE AUTO ADVISOR – FITNESS / PASSING REMINDER* 📍 *Morbi* 🧾 *શ્રી FUSION GRANITO PVT LTD sir*, તમારી ગાડી *GJ36S2655* નું *પાસિંગ (Fitness) તા. 03-01-2026* એ પૂરું થાય છે. ⚠️ પાસિંગ સમયસર ન કરાવવાથી ઓનલાઇન મેમો આવી શકે છે. કૃપા કરીને પાસિંગ નિયમિત રીતે કરાવજો.પાસિંગ ચાલુ ના હોય તો વીમા ક્લેમ પાસ થતો નથી. ✅ અમારી પાસે પાસિંગ, પરમીટ, લાઇસન્સ, નામ ટ્રાન્સફર, વીમો વગેરે RTO ને લગતી તમામ સર્વિસ ઉપલબ્ધ છે. — 📞 સંપર્ક કરો: ANJALI-8141489538 | 8141488962 🏢 *ટોર્ક ઓટો એડવાઇઝર* બીજા માળે, જીલ કોમ્પલેક્સ, અયોધ્યાપૂરી રોડ, જૂના બસ સ્ટેન્ડ પાસે, મોરબી 🌐 www.torqueautoadvisor.com ✉️ info@torqueautoadvisor.com GST No. 24ALBPL1123D1ZY IRDA Code: 1980390000 MSME: UDYAM-GJ-32-0014559 📍 Office Location: https://share.google/IdNJCnrf2jFCWten6
A24: ANJALI-8141489538 | B24: GJ02ZZ7524 | C24: AJEET | D24: 46025 | E24: 42000 | F24: 16/09/19 | G24: 9979103215 | H24: ="💬 *TORQUE AUTO ADVISOR – FITNESS / PASSING REMINDER* " & CHAR(10) & "📍 *Morbi*" & CHAR(10) & CHAR(10) & "🧾 *શ્રી " & C24 & " sir*, તમારી ગાડી *" & B24 & "* નું *પાસિંગ (Fitness) તા. " & TEXT(D24,"DD-MM-yyyy") & "* એ પૂરું થાય છે." & CHAR(10) & CHAR(10) & "⚠️ પાસિંગ સમયસર ન કરાવવાથી ઓનલાઇન મેમો આવી શકે છે. કૃપા કરીને પાસિંગ નિયમિત રીતે કરાવજો.પાસિંગ ચાલુ ના હોય તો વીમા ક્લેમ પાસ થતો નથી." & CHAR(10) & CHAR(10) & "✅ અમારી પાસે પાસિંગ, પરમીટ, લાઇસન્સ, નામ ટ્રાન્સફર, વીમો વગેરે RTO ને લગતી તમામ સર્વિસ ઉપલબ્ધ છે. —" & CHAR(10) & "📞 સંપર્ક કરો: " & A24 & " | 8141488962" & CHAR(10) & CHAR(10) & "🏢 *ટોર્ક ઓટો એડવાઇઝર*" & CHAR(10) & "બીજા માળે, જીલ કોમ્પલેક્સ, અયોધ્યાપૂરી રોડ," & CHAR(10) & "જૂના બસ સ્ટેન્ડ પાસે, મોરબી" & CHAR(10) & CHAR(10) & "🌐 www.torqueautoadvisor.com" & CHAR(10) & "✉️ info@torqueautoadvisor.com" & CHAR(10) & CHAR(10) & "GST No. 24ALBPL1123D1ZY" & CHAR(10) & "IRDA Code: 1980390000" & CHAR(10) & "MSME: UDYAM-GJ-32-0014559"& CHAR(10) & CHAR(10) & "📍 Office Location: https://share.google/IdNJCnrf2jFCWten6" -> 💬 *TORQUE AUTO ADVISOR – FITNESS / PASSING REMINDER* 📍 *Morbi* 🧾 *શ્રી AJEET sir*, તમારી ગાડી *GJ02ZZ7524* નું *પાસિંગ (Fitness) તા. 03-01-2026* એ પૂરું થાય છે. ⚠️ પાસિંગ સમયસર ન કરાવવાથી ઓનલાઇન મેમો આવી શકે છે. કૃપા કરીને પાસિંગ નિયમિત રીતે કરાવજો.પાસિંગ ચાલુ ના હોય તો વીમા ક્લેમ પાસ થતો નથી. ✅ અમારી પાસે પાસિંગ, પરમીટ, લાઇસન્સ, નામ ટ્રાન્સફર, વીમો વગેરે RTO ને લગતી તમામ સર્વિસ ઉપલબ્ધ છે. — 📞 સંપર્ક કરો: ANJALI-8141489538 | 8141488962 🏢 *ટોર્ક ઓટો એડવાઇઝર* બીજા માળે, જીલ કોમ્પલેક્સ, અયોધ્યાપૂરી રોડ, જૂના બસ સ્ટેન્ડ પાસે, મોરબી 🌐 www.torqueautoadvisor.com ✉️ info@torqueautoadvisor.com GST No. 24ALBPL1123D1ZY IRDA Code: 1980390000 MSME: UDYAM-GJ-32-0014559 📍 Office Location: https://share.google/IdNJCnrf2jFCWten6
A25: ANJALI-8141489538 | B25: GJ13AV7047 | C25: VIKRAMBHAI | D25: 46026 | E25: 717 | F25: 45413 | G25: 6351099617 | H25: ="💬 *TORQUE AUTO ADVISOR – FITNESS / PASSING REMINDER* " & CHAR(10) & "📍 *Morbi*" & CHAR(10) & CHAR(10) & "🧾 *શ્રી " & C25 & " sir*, તમારી ગાડી *" & B25 & "* નું *પાસિંગ (Fitness) તા. " & TEXT(D25,"DD-MM-yyyy") & "* એ પૂરું થાય છે." & CHAR(10) & CHAR(10) & "⚠️ પાસિંગ સમયસર ન કરાવવાથી ઓનલાઇન મેમો આવી શકે છે. કૃપા કરીને પાસિંગ નિયમિત રીતે કરાવજો.પાસિંગ ચાલુ ના હોય તો વીમા ક્લેમ પાસ થતો નથી." & CHAR(10) & CHAR(10) & "✅ અમારી પાસે પાસિંગ, પરમીટ, લાઇસન્સ, નામ ટ્રાન્સફર, વીમો વગેરે RTO ને લગતી તમામ સર્વિસ ઉપલબ્ધ છે. —" & CHAR(10) & "📞 સંપર્ક કરો: " & A25 & " | 8141488962" & CHAR(10) & CHAR(10) & "🏢 *ટોર્ક ઓટો એડવાઇઝર*" & CHAR(10) & "બીજા માળે, જીલ કોમ્પલેક્સ, અયોધ્યાપૂરી રોડ," & CHAR(10) & "જૂના બસ સ્ટેન્ડ પાસે, મોરબી" & CHAR(10) & CHAR(10) & "🌐 www.torqueautoadvisor.com" & CHAR(10) & "✉️ info@torqueautoadvisor.com" & CHAR(10) & CHAR(10) & "GST No. 24ALBPL1123D1ZY" & CHAR(10) & "IRDA Code: 1980390000" & CHAR(10) & "MSME: UDYAM-GJ-32-0014559"& CHAR(10) & CHAR(10) & "📍 Office Location: https://share.google/IdNJCnrf2jFCWten6" -> 💬 *TORQUE AUTO ADVISOR – FITNESS / PASSING REMINDER* 📍 *Morbi* 🧾 *શ્રી VIKRAMBHAI sir*, તમારી ગાડી *GJ13AV7047* નું *પાસિંગ (Fitness) તા. 04-01-2026* એ પૂરું થાય છે. ⚠️ પાસિંગ સમયસર ન કરાવવાથી ઓનલાઇન મેમો આવી શકે છે. કૃપા કરીને પાસિંગ નિયમિત રીતે કરાવજો.પાસિંગ ચાલુ ના હોય તો વીમા ક્લેમ પાસ થતો નથી. ✅ અમારી પાસે પાસિંગ, પરમીટ, લાઇસન્સ, નામ ટ્રાન્સફર, વીમો વગેરે RTO ને લગતી તમામ સર્વિસ ઉપલબ્ધ છે. — 📞 સંપર્ક કરો: ANJALI-8141489538 | 8141488962 🏢 *ટોર્ક ઓટો એડવાઇઝર* બીજા માળે, જીલ કોમ્પલેક્સ, અયોધ્યાપૂરી રોડ, જૂના બસ સ્ટેન્ડ પાસે, મોરબી 🌐 www.torqueautoadvisor.com ✉️ info@torqueautoadvisor.com GST No. 24ALBPL1123D1ZY IRDA Code: 1980390000 MSME: UDYAM-GJ-32-0014559 📍 Office Location: https://share.google/IdNJCnrf2jFCWten6
A26: ANJALI-8141489538 | B26: GJ36V2792 | C26: KANDHABHAI VIRAMBHAI PARMAR | D26: 46026 | E26: 47500 | F26: 44682 | G26: 7435929092 | H26: ="💬 *TORQUE AUTO ADVISOR – FITNESS / PASSING REMINDER* " & CHAR(10) & "📍 *Morbi*" & CHAR(10) & CHAR(10) & "🧾 *શ્રી " & C26 & " sir*, તમારી ગાડી *" & B26 & "* નું *પાસિંગ (Fitness) તા. " & TEXT(D26,"DD-MM-yyyy") & "* એ પૂરું થાય છે." & CHAR(10) & CHAR(10) & "⚠️ પાસિંગ સમયસર ન કરાવવાથી ઓનલાઇન મેમો આવી શકે છે. કૃપા કરીને પાસિંગ નિયમિત રીતે કરાવજો.પાસિંગ ચાલુ ના હોય તો વીમા ક્લેમ પાસ થતો નથી." & CHAR(10) & CHAR(10) & "✅ અમારી પાસે પાસિંગ, પરમીટ, લાઇસન્સ, નામ ટ્રાન્સફર, વીમો વગેરે RTO ને લગતી તમામ સર્વિસ ઉપલબ્ધ છે. —" & CHAR(10) & "📞 સંપર્ક કરો: " & A26 & " | 8141488962" & CHAR(10) & CHAR(10) & "🏢 *ટોર્ક ઓટો એડવાઇઝર*" & CHAR(10) & "બીજા માળે, જીલ કોમ્પલેક્સ, અયોધ્યાપૂરી રોડ," & CHAR(10) & "જૂના બસ સ્ટેન્ડ પાસે, મોરબી" & CHAR(10) & CHAR(10) & "🌐 www.torqueautoadvisor.com" & CHAR(10) & "✉️ info@torqueautoadvisor.com" & CHAR(10) & CHAR(10) & "GST No. 24ALBPL1123D1ZY" & CHAR(10) & "IRDA Code: 1980390000" & CHAR(10) & "MSME: UDYAM-GJ-32-0014559"& CHAR(10) & CHAR(10) & "📍 Office Location: https://share.google/IdNJCnrf2jFCWten6" -> 💬 *TORQUE AUTO ADVISOR – FITNESS / PASSING REMINDER* 📍 *Morbi* 🧾 *શ્રી KANDHABHAI VIRAMBHAI PARMAR sir*, તમારી ગાડી *GJ36V2792* નું *પાસિંગ (Fitness) તા. 04-01-2026* એ પૂરું થાય છે. ⚠️ પાસિંગ સમયસર ન કરાવવાથી ઓનલાઇન મેમો આવી શકે છે. કૃપા કરીને પાસિંગ નિયમિત રીતે કરાવજો.પાસિંગ ચાલુ ના હોય તો વીમા ક્લેમ પાસ થતો નથી. ✅ અમારી પાસે પાસિંગ, પરમીટ, લાઇસન્સ, નામ ટ્રાન્સફર, વીમો વગેરે RTO ને લગતી તમામ સર્વિસ ઉપલબ્ધ છે. — 📞 સંપર્ક કરો: ANJALI-8141489538 | 8141488962 🏢 *ટોર્ક ઓટો એડવાઇઝર* બીજા માળે, જીલ કોમ્પલેક્સ, અયોધ્યાપૂરી રોડ, જૂના બસ સ્ટેન્ડ પાસે, મોરબી 🌐 www.torqueautoadvisor.com ✉️ info@torqueautoadvisor.com GST No. 24ALBPL1123D1ZY IRDA Code: 1980390000 MSME: UDYAM-GJ-32-0014559 📍 Office Location: https://share.google/IdNJCnrf2jFCWten6
A27: ANJALI-8141489538 | B27: GJ36V3592 | C27: KANDHABHAI VIRAMBHAI PARMAR | D27: 46026 | E27: 47500 | F27: 44682 | G27: 7435929092 | H27: ="💬 *TORQUE AUTO ADVISOR – FITNESS / PASSING REMINDER* " & CHAR(10) & "📍 *Morbi*" & CHAR(10) & CHAR(10) & "🧾 *શ્રી " & C27 & " sir*, તમારી ગાડી *" & B27 & "* નું *પાસિંગ (Fitness) તા. " & TEXT(D27,"DD-MM-yyyy") & "* એ પૂરું થાય છે." & CHAR(10) & CHAR(10) & "⚠️ પાસિંગ સમયસર ન કરાવવાથી ઓનલાઇન મેમો આવી શકે છે. કૃપા કરીને પાસિંગ નિયમિત રીતે કરાવજો.પાસિંગ ચાલુ ના હોય તો વીમા ક્લેમ પાસ થતો નથી." & CHAR(10) & CHAR(10) & "✅ અમારી પાસે પાસિંગ, પરમીટ, લાઇસન્સ, નામ ટ્રાન્સફર, વીમો વગેરે RTO ને લગતી તમામ સર્વિસ ઉપલબ્ધ છે. —" & CHAR(10) & "📞 સંપર્ક કરો: " & A27 & " | 8141488962" & CHAR(10) & CHAR(10) & "🏢 *ટોર્ક ઓટો એડવાઇઝર*" & CHAR(10) & "બીજા માળે, જીલ કોમ્પલેક્સ, અયોધ્યાપૂરી રોડ," & CHAR(10) & "જૂના બસ સ્ટેન્ડ પાસે, મોરબી" & CHAR(10) & CHAR(10) & "🌐 www.torqueautoadvisor.com" & CHAR(10) & "✉️ info@torqueautoadvisor.com" & CHAR(10) & CHAR(10) & "GST No. 24ALBPL1123D1ZY" & CHAR(10) & "IRDA Code: 1980390000" & CHAR(10) & "MSME: UDYAM-GJ-32-0014559"& CHAR(10) & CHAR(10) & "📍 Office Location: https://share.google/IdNJCnrf2jFCWten6" -> 💬 *TORQUE AUTO ADVISOR – FITNESS / PASSING REMINDER* 📍 *Morbi* 🧾 *શ્રી KANDHABHAI VIRAMBHAI PARMAR sir*, તમારી ગાડી *GJ36V3592* નું *પાસિંગ (Fitness) તા. 04-01-2026* એ પૂરું થાય છે. ⚠️ પાસિંગ સમયસર ન કરાવવાથી ઓનલાઇન મેમો આવી શકે છે. કૃપા કરીને પાસિંગ નિયમિત રીતે કરાવજો.પાસિંગ ચાલુ ના હોય તો વીમા ક્લેમ પાસ થતો નથી. ✅ અમારી પાસે પાસિંગ, પરમીટ, લાઇસન્સ, નામ ટ્રાન્સફર, વીમો વગેરે RTO ને લગતી તમામ સર્વિસ ઉપલબ્ધ છે. — 📞 સંપર્ક કરો: ANJALI-8141489538 | 8141488962 🏢 *ટોર્ક ઓટો એડવાઇઝર* બીજા માળે, જીલ કોમ્પલેક્સ, અયોધ્યાપૂરી રોડ, જૂના બસ સ્ટેન્ડ પાસે, મોરબી 🌐 www.torqueautoadvisor.com ✉️ info@torqueautoadvisor.com GST No. 24ALBPL1123D1ZY IRDA Code: 1980390000 MSME: UDYAM-GJ-32-0014559 📍 Office Location: https://share.google/IdNJCnrf2jFCWten6
A28: ANJALI-8141489538 | B28: GJ36V3692 | C28: KANDHABHAI VIRAMBHAI PARMAR | D28: 46026 | E28: 47500 | F28: 44682 | G28: 7435929092 | H28: ="💬 *TORQUE AUTO ADVISOR – FITNESS / PASSING REMINDER* " & CHAR(10) & "📍 *Morbi*" & CHAR(10) & CHAR(10) & "🧾 *શ્રી " & C28 & " sir*, તમારી ગાડી *" & B28 & "* નું *પાસિંગ (Fitness) તા. " & TEXT(D28,"DD-MM-yyyy") & "* એ પૂરું થાય છે." & CHAR(10) & CHAR(10) & "⚠️ પાસિંગ સમયસર ન કરાવવાથી ઓનલાઇન મેમો આવી શકે છે. કૃપા કરીને પાસિંગ નિયમિત રીતે કરાવજો.પાસિંગ ચાલુ ના હોય તો વીમા ક્લેમ પાસ થતો નથી." & CHAR(10) & CHAR(10) & "✅ અમારી પાસે પાસિંગ, પરમીટ, લાઇસન્સ, નામ ટ્રાન્સફર, વીમો વગેરે RTO ને લગતી તમામ સર્વિસ ઉપલબ્ધ છે. —" & CHAR(10) & "📞 સંપર્ક કરો: " & A28 & " | 8141488962" & CHAR(10) & CHAR(10) & "🏢 *ટોર્ક ઓટો એડવાઇઝર*" & CHAR(10) & "બીજા માળે, જીલ કોમ્પલેક્સ, અયોધ્યાપૂરી રોડ," & CHAR(10) & "જૂના બસ સ્ટેન્ડ પાસે, મોરબી" & CHAR(10) & CHAR(10) & "🌐 www.torqueautoadvisor.com" & CHAR(10) & "✉️ info@torqueautoadvisor.com" & CHAR(10) & CHAR(10) & "GST No. 24ALBPL1123D1ZY" & CHAR(10) & "IRDA Code: 1980390000" & CHAR(10) & "MSME: UDYAM-GJ-32-0014559"& CHAR(10) & CHAR(10) & "📍 Office Location: https://share.google/IdNJCnrf2jFCWten6" -> 💬 *TORQUE AUTO ADVISOR – FITNESS / PASSING REMINDER* 📍 *Morbi* 🧾 *શ્રી KANDHABHAI VIRAMBHAI PARMAR sir*, તમારી ગાડી *GJ36V3692* નું *પાસિંગ (Fitness) તા. 04-01-2026* એ પૂરું થાય છે. ⚠️ પાસિંગ સમયસર ન કરાવવાથી ઓનલાઇન મેમો આવી શકે છે. કૃપા કરીને પાસિંગ નિયમિત રીતે કરાવજો.પાસિંગ ચાલુ ના હોય તો વીમા ક્લેમ પાસ થતો નથી. ✅ અમારી પાસે પાસિંગ, પરમીટ, લાઇસન્સ, નામ ટ્રાન્સફર, વીમો વગેરે RTO ને લગતી તમામ સર્વિસ ઉપલબ્ધ છે. — 📞 સંપર્ક કરો: ANJALI-8141489538 | 8141488962 🏢 *ટોર્ક ઓટો એડવાઇઝર* બીજા માળે, જીલ કોમ્પલેક્સ, અયોધ્યાપૂરી રોડ, જૂના બસ સ્ટેન્ડ પાસે, મોરબી 🌐 www.torqueautoadvisor.com ✉️ info@torqueautoadvisor.com GST No. 24ALBPL1123D1ZY IRDA Code: 1980390000 MSME: UDYAM-GJ-32-0014559 📍 Office Location: https://share.google/IdNJCnrf2jFCWten6
A29: ANJALI-8141489538 | B29: GJ36V4592 | C29: KANDHABHAI VIRAMBHAI PARMAR | D29: 46026 | E29: 47500 | F29: 44682 | G29: 7435929092 | H29: ="💬 *TORQUE AUTO ADVISOR – FITNESS / PASSING REMINDER* " & CHAR(10) & "📍 *Morbi*" & CHAR(10) & CHAR(10) & "🧾 *શ્રી " & C29 & " sir*, તમારી ગાડી *" & B29 & "* નું *પાસિંગ (Fitness) તા. " & TEXT(D29,"DD-MM-yyyy") & "* એ પૂરું થાય છે." & CHAR(10) & CHAR(10) & "⚠️ પાસિંગ સમયસર ન કરાવવાથી ઓનલાઇન મેમો આવી શકે છે. કૃપા કરીને પાસિંગ નિયમિત રીતે કરાવજો.પાસિંગ ચાલુ ના હોય તો વીમા ક્લેમ પાસ થતો નથી." & CHAR(10) & CHAR(10) & "✅ અમારી પાસે પાસિંગ, પરમીટ, લાઇસન્સ, નામ ટ્રાન્સફર, વીમો વગેરે RTO ને લગતી તમામ સર્વિસ ઉપલબ્ધ છે. —" & CHAR(10) & "📞 સંપર્ક કરો: " & A29 & " | 8141488962" & CHAR(10) & CHAR(10) & "🏢 *ટોર્ક ઓટો એડવાઇઝર*" & CHAR(10) & "બીજા માળે, જીલ કોમ્પલેક્સ, અયોધ્યાપૂરી રોડ," & CHAR(10) & "જૂના બસ સ્ટેન્ડ પાસે, મોરબી" & CHAR(10) & CHAR(10) & "🌐 www.torqueautoadvisor.com" & CHAR(10) & "✉️ info@torqueautoadvisor.com" & CHAR(10) & CHAR(10) & "GST No. 24ALBPL1123D1ZY" & CHAR(10) & "IRDA Code: 1980390000" & CHAR(10) & "MSME: UDYAM-GJ-32-0014559"& CHAR(10) & CHAR(10) & "📍 Office Location: https://share.google/IdNJCnrf2jFCWten6" -> 💬 *TORQUE AUTO ADVISOR – FITNESS / PASSING REMINDER* 📍 *Morbi* 🧾 *શ્રી KANDHABHAI VIRAMBHAI PARMAR sir*, તમારી ગાડી *GJ36V4592* નું *પાસિંગ (Fitness) તા. 04-01-2026* એ પૂરું થાય છે. ⚠️ પાસિંગ સમયસર ન કરાવવાથી ઓનલાઇન મેમો આવી શકે છે. કૃપા કરીને પાસિંગ નિયમિત રીતે કરાવજો.પાસિંગ ચાલુ ના હોય તો વીમા ક્લેમ પાસ થતો નથી. ✅ અમારી પાસે પાસિંગ, પરમીટ, લાઇસન્સ, નામ ટ્રાન્સફર, વીમો વગેરે RTO ને લગતી તમામ સર્વિસ ઉપલબ્ધ છે. — 📞 સંપર્ક કરો: ANJALI-8141489538 | 8141488962 🏢 *ટોર્ક ઓટો એડવાઇઝર* બીજા માળે, જીલ કોમ્પલેક્સ, અયોધ્યાપૂરી રોડ, જૂના બસ સ્ટેન્ડ પાસે, મોરબી 🌐 www.torqueautoadvisor.com ✉️ info@torqueautoadvisor.com GST No. 24ALBPL1123D1ZY IRDA Code: 1980390000 MSME: UDYAM-GJ-32-0014559 📍 Office Location: https://share.google/IdNJCnrf2jFCWten6
A30: ANJALI-8141489538 | B30: GJ36V8092 | C30: KANDHABHAI VIRAMBHAI PARMAR | D30: 46026 | E30: 47500 | F30: 44682 | G30: 7435929092 | H30: ="💬 *TORQUE AUTO ADVISOR – FITNESS / PASSING REMINDER* " & CHAR(10) & "📍 *Morbi*" & CHAR(10) & CHAR(10) & "🧾 *શ્રી " & C30 & " sir*, તમારી ગાડી *" & B30 & "* નું *પાસિંગ (Fitness) તા. " & TEXT(D30,"DD-MM-yyyy") & "* એ પૂરું થાય છે." & CHAR(10) & CHAR(10) & "⚠️ પાસિંગ સમયસર ન કરાવવાથી ઓનલાઇન મેમો આવી શકે છે. કૃપા કરીને પાસિંગ નિયમિત રીતે કરાવજો.પાસિંગ ચાલુ ના હોય તો વીમા ક્લેમ પાસ થતો નથી." & CHAR(10) & CHAR(10) & "✅ અમારી પાસે પાસિંગ, પરમીટ, લાઇસન્સ, નામ ટ્રાન્સફર, વીમો વગેરે RTO ને લગતી તમામ સર્વિસ ઉપલબ્ધ છે. —" & CHAR(10) & "📞 સંપર્ક કરો: " & A30 & " | 8141488962" & CHAR(10) & CHAR(10) & "🏢 *ટોર્ક ઓટો એડવાઇઝર*" & CHAR(10) & "બીજા માળે, જીલ કોમ્પલેક્સ, અયોધ્યાપૂરી રોડ," & CHAR(10) & "જૂના બસ સ્ટેન્ડ પાસે, મોરબી" & CHAR(10) & CHAR(10) & "🌐 www.torqueautoadvisor.com" & CHAR(10) & "✉️ info@torqueautoadvisor.com" & CHAR(10) & CHAR(10) & "GST No. 24ALBPL1123D1ZY" & CHAR(10) & "IRDA Code: 1980390000" & CHAR(10) & "MSME: UDYAM-GJ-32-0014559"& CHAR(10) & CHAR(10) & "📍 Office Location: https://share.google/IdNJCnrf2jFCWten6" -> 💬 *TORQUE AUTO ADVISOR – FITNESS / PASSING REMINDER* 📍 *Morbi* 🧾 *શ્રી KANDHABHAI VIRAMBHAI PARMAR sir*, તમારી ગાડી *GJ36V8092* નું *પાસિંગ (Fitness) તા. 04-01-2026* એ પૂરું થાય છે. ⚠️ પાસિંગ સમયસર ન કરાવવાથી ઓનલાઇન મેમો આવી શકે છે. કૃપા કરીને પાસિંગ નિયમિત રીતે કરાવજો.પાસિંગ ચાલુ ના હોય તો વીમા ક્લેમ પાસ થતો નથી. ✅ અમારી પાસે પાસિંગ, પરમીટ, લાઇસન્સ, નામ ટ્રાન્સફર, વીમો વગેરે RTO ને લગતી તમામ સર્વિસ ઉપલબ્ધ છે. — 📞 સંપર્ક કરો: ANJALI-8141489538 | 8141488962 🏢 *ટોર્ક ઓટો એડવાઇઝર* બીજા માળે, જીલ કોમ્પલેક્સ, અયોધ્યાપૂરી રોડ, જૂના બસ સ્ટેન્ડ પાસે, મોરબી 🌐 www.torqueautoadvisor.com ✉️ info@torqueautoadvisor.com GST No. 24ALBPL1123D1ZY IRDA Code: 1980390000 MSME: UDYAM-GJ-32-0014559 📍 Office Location: https://share.google/IdNJCnrf2jFCWten6
A31: ANJALI-8141489538 | B31: GJ36S2194 | C31: KOLI JITESHBHAINAGRAJBHAI | D31: 46026 | E31: 2980 | F31: 16/12/20 | G31: 8238203808 | H31: ="💬 *TORQUE AUTO ADVISOR – FITNESS / PASSING REMINDER* " & CHAR(10) & "📍 *Morbi*" & CHAR(10) & CHAR(10) & "🧾 *શ્રી " & C31 & " sir*, તમારી ગાડી *" & B31 & "* નું *પાસિંગ (Fitness) તા. " & TEXT(D31,"DD-MM-yyyy") & "* એ પૂરું થાય છે." & CHAR(10) & CHAR(10) & "⚠️ પાસિંગ સમયસર ન કરાવવાથી ઓનલાઇન મેમો આવી શકે છે. કૃપા કરીને પાસિંગ નિયમિત રીતે કરાવજો.પાસિંગ ચાલુ ના હોય તો વીમા ક્લેમ પાસ થતો નથી." & CHAR(10) & CHAR(10) & "✅ અમારી પાસે પાસિંગ, પરમીટ, લાઇસન્સ, નામ ટ્રાન્સફર, વીમો વગેરે RTO ને લગતી તમામ સર્વિસ ઉપલબ્ધ છે. —" & CHAR(10) & "📞 સંપર્ક કરો: " & A31 & " | 8141488962" & CHAR(10) & CHAR(10) & "🏢 *ટોર્ક ઓટો એડવાઇઝર*" & CHAR(10) & "બીજા માળે, જીલ કોમ્પલેક્સ, અયોધ્યાપૂરી રોડ," & CHAR(10) & "જૂના બસ સ્ટેન્ડ પાસે, મોરબી" & CHAR(10) & CHAR(10) & "🌐 www.torqueautoadvisor.com" & CHAR(10) & "✉️ info@torqueautoadvisor.com" & CHAR(10) & CHAR(10) & "GST No. 24ALBPL1123D1ZY" & CHAR(10) & "IRDA Code: 1980390000" & CHAR(10) & "MSME: UDYAM-GJ-32-0014559"& CHAR(10) & CHAR(10) & "📍 Office Location: https://share.google/IdNJCnrf2jFCWten6" -> 💬 *TORQUE AUTO ADVISOR – FITNESS / PASSING REMINDER* 📍 *Morbi* 🧾 *શ્રી KOLI JITESHBHAINAGRAJBHAI sir*, તમારી ગાડી *GJ36S2194* નું *પાસિંગ (Fitness) તા. 04-01-2026* એ પૂરું થાય છે. ⚠️ પાસિંગ સમયસર ન કરાવવાથી ઓનલાઇન મેમો આવી શકે છે. કૃપા કરીને પાસિંગ નિયમિત રીતે કરાવજો.પાસિંગ ચાલુ ના હોય તો વીમા ક્લેમ પાસ થતો નથી. ✅ અમારી પાસે પાસિંગ, પરમીટ, લાઇસન્સ, નામ ટ્રાન્સફર, વીમો વગેરે RTO ને લગતી તમામ સર્વિસ ઉપલબ્ધ છે. — 📞 સંપર્ક કરો: ANJALI-8141489538 | 8141488962 🏢 *ટોર્ક ઓટો એડવાઇઝર* બીજા માળે, જીલ કોમ્પલેક્સ, અયોધ્યાપૂરી રોડ, જૂના બસ સ્ટેન્ડ પાસે, મોરબી 🌐 www.torqueautoadvisor.com ✉️ info@torqueautoadvisor.com GST No. 24ALBPL1123D1ZY IRDA Code: 1980390000 MSME: UDYAM-GJ-32-0014559 📍 Office Location: https://share.google/IdNJCnrf2jFCWten6
A32: ANJALI-8141489538 | B32: GJ36T5576 | C32: MOMBHAI | D32: 46026 | E32: 1550 | F32: 43468 | G32: 9099709231 | H32: ="💬 *TORQUE AUTO ADVISOR – FITNESS / PASSING REMINDER* " & CHAR(10) & "📍 *Morbi*" & CHAR(10) & CHAR(10) & "🧾 *શ્રી " & C32 & " sir*, તમારી ગાડી *" & B32 & "* નું *પાસિંગ (Fitness) તા. " & TEXT(D32,"DD-MM-yyyy") & "* એ પૂરું થાય છે." & CHAR(10) & CHAR(10) & "⚠️ પાસિંગ સમયસર ન કરાવવાથી ઓનલાઇન મેમો આવી શકે છે. કૃપા કરીને પાસિંગ નિયમિત રીતે કરાવજો.પાસિંગ ચાલુ ના હોય તો વીમા ક્લેમ પાસ થતો નથી." & CHAR(10) & CHAR(10) & "✅ અમારી પાસે પાસિંગ, પરમીટ, લાઇસન્સ, નામ ટ્રાન્સફર, વીમો વગેરે RTO ને લગતી તમામ સર્વિસ ઉપલબ્ધ છે. —" & CHAR(10) & "📞 સંપર્ક કરો: " & A32 & " | 8141488962" & CHAR(10) & CHAR(10) & "🏢 *ટોર્ક ઓટો એડવાઇઝર*" & CHAR(10) & "બીજા માળે, જીલ કોમ્પલેક્સ, અયોધ્યાપૂરી રોડ," & CHAR(10) & "જૂના બસ સ્ટેન્ડ પાસે, મોરબી" & CHAR(10) & CHAR(10) & "🌐 www.torqueautoadvisor.com" & CHAR(10) & "✉️ info@torqueautoadvisor.com" & CHAR(10) & CHAR(10) & "GST No. 24ALBPL1123D1ZY" & CHAR(10) & "IRDA Code: 1980390000" & CHAR(10) & "MSME: UDYAM-GJ-32-0014559"& CHAR(10) & CHAR(10) & "📍 Office Location: https://share.google/IdNJCnrf2jFCWten6" -> 💬 *TORQUE AUTO ADVISOR – FITNESS / PASSING REMINDER* 📍 *Morbi* 🧾 *શ્રી MOMBHAI sir*, તમારી ગાડી *GJ36T5576* નું *પાસિંગ (Fitness) તા. 04-01-2026* એ પૂરું થાય છે. ⚠️ પાસિંગ સમયસર ન કરાવવાથી ઓનલાઇન મેમો આવી શકે છે. કૃપા કરીને પાસિંગ નિયમિત રીતે કરાવજો.પાસિંગ ચાલુ ના હોય તો વીમા ક્લેમ પાસ થતો નથી. ✅ અમારી પાસે પાસિંગ, પરમીટ, લાઇસન્સ, નામ ટ્રાન્સફર, વીમો વગેરે RTO ને લગતી તમામ સર્વિસ ઉપલબ્ધ છે. — 📞 સંપર્ક કરો: ANJALI-8141489538 | 8141488962 🏢 *ટોર્ક ઓટો એડવાઇઝર* બીજા માળે, જીલ કોમ્પલેક્સ, અયોધ્યાપૂરી રોડ, જૂના બસ સ્ટેન્ડ પાસે, મોરબી 🌐 www.torqueautoadvisor.com ✉️ info@torqueautoadvisor.com GST No. 24ALBPL1123D1ZY IRDA Code: 1980390000 MSME: UDYAM-GJ-32-0014559 📍 Office Location: https://share.google/IdNJCnrf2jFCWten6
